Workbook
Name BG_Multiplier_Weight: 'BG Calc'!$AA$3:$AA$5
Name BG_Opt_Weight: 'BG Calc'!$AG$18:$AG$52
Name BG_Opt0_Weight: 'BG Calc'!$AK$20:$AK$25
Name BG_Opt1_Weight: 'BG Calc'!$AL$20:$AL$25
Name BG_Reel_Weight: 'BG Calc'!$AF$3:$AF$11
Name BG1_Reel1: 'BG1 Reel'!$C$10:$C$82
Name BG1_Reel2: 'BG1 Reel'!$D$10:$D$71
Name BG1_Reel3: 'BG1 Reel'!$E$10:$E$53
Name BG1_Reel4: 'BG1 Reel'!$F$10:$F$68
Name BG1_Reel5: 'BG1 Reel'!$G$10:$G$47
Name BG1_Reel6: 'BG1 Reel'!$H$10:$H$92
Name BG2_Reel1: 'BG2 Reel'!$C$10:$C$96
Name BG2_Reel2: 'BG2 Reel'!$D$10:$D$46
Name BG2_Reel3: 'BG2 Reel'!$E$10:$E$88
Name BG2_Reel4: 'BG2 Reel'!$F$10:$F$84
Name BG2_Reel5: 'BG2 Reel'!$G$10:$G$108
Name BG2_Reel6: 'BG2 Reel'!$H$10:$H$109
Name BG3_Reel1: 'BG3 Reel'!$C$10:$C$108
Name BG3_Reel2: 'BG3 Reel'!$D$10:$D$80
Name BG3_Reel3: 'BG3 Reel'!$E$10:$E$88
Name BG3_Reel4: 'BG3 Reel'!$F$10:$F$86
Name BG3_Reel5: 'BG3 Reel'!$G$10:$G$64
Name BG3_Reel6: 'BG3 Reel'!$H$10:$H$48
Name BG4_Reel1: 'BG4 Reel'!$C$10:$C$96
Name BG4_Reel2: 'BG4 Reel'!$D$10:$D$61
Name BG4_Reel3: 'BG4 Reel'!$E$10:$E$108
Name BG4_Reel4: 'BG4 Reel'!$F$10:$F$74
Name BG4_Reel5: 'BG4 Reel'!$G$10:$G$50
Name BG4_Reel6: 'BG4 Reel'!$H$10:$H$78
Name BG5_Reel1: 'BG5 Reel'!$C$10:$C$68
Name BG5_Reel2: 'BG5 Reel'!$D$10:$D$100
Name BG5_Reel3: 'BG5 Reel'!$E$10:$E$86
Name BG5_Reel4: 'BG5 Reel'!$F$10:$F$60
Name BG5_Reel5: 'BG5 Reel'!$G$10:$G$70
Name BG5_Reel6: 'BG5 Reel'!$H$10:$H$95
Name BG6_Reel1: 'BG6 Reel'!$C$10:$C$27
Name BG6_Reel2: 'BG6 Reel'!$D$10:$D$46
Name BG6_Reel3: 'BG6 Reel'!$E$10:$E$58
Name BG6_Reel4: 'BG6 Reel'!$F$10:$F$79
Name BG6_Reel5: 'BG6 Reel'!$G$10:$G$101
Name BG6_Reel6: 'BG6 Reel'!$H$10:$H$97
Name BG7_Reel1: 'BG7 Reel'!$C$10:$C$90
Name BG7_Reel2: 'BG7 Reel'!$D$10:$D$66
Name BG7_Reel3: 'BG7 Reel'!$E$10:$E$89
Name BG7_Reel4: 'BG7 Reel'!$F$10:$F$47
Name BG7_Reel5: 'BG7 Reel'!$G$10:$G$82
Name BG7_Reel6: 'BG7 Reel'!$H$10:$H$79
Name BG8_Reel1: 'BG8 Reel'!$C$10:$C$54
Name BG8_Reel2: 'BG8 Reel'!$D$10:$D$69
Name BG8_Reel3: 'BG8 Reel'!$E$10:$E$99
Name BG8_Reel4: 'BG8 Reel'!$F$10:$F$55
Name BG8_Reel5: 'BG8 Reel'!$G$10:$G$54
Name BG8_Reel6: 'BG8 Reel'!$H$10:$H$106
Name BG9_Reel1: 'BG9 Reel'!$C$10:$C$88
Name BG9_Reel2: 'BG9 Reel'!$D$10:$D$76
Name BG9_Reel3: 'BG9 Reel'!$E$10:$E$73
Name BG9_Reel4: 'BG9 Reel'!$F$10:$F$100
Name BG9_Reel5: 'BG9 Reel'!$G$10:$G$100
Name BG9_Reel6: 'BG9 Reel'!$H$10:$H$106
Name Buy_FG1_Multiplier_Weight: 'Buy FG1 Calc'!$AA$3:$AA$5

Sheet Summary
J1: Whole Game | M1: Buy Bonus 1 | P1: Buy Bonus 2
B2: Normal Game | J2: Game Name: | K2: DogHouseMegaways9700 | M2: Game Name: | N2: DogHouseMegaways9700 | P2: Game Name: | Q2: DogHouseMegaways9700
C3: RTP | D3: Odds | E3: Avg. | J3: Number of Simulations: | K3: 1000000000 | M3: Number of Simulations: | N3: 10000000 | P3: Number of Simulations: | Q3: 10000000
B4: Base Game | C4: =K7 -> 0.6892386 | J4: Number of Lines Played: | K4: 20 | M4: Number of Lines Played: | N4: 20 | P4: Number of Lines Played: | Q4: 20
B5: Wheel Bonus | C5: =K17 -> 0.2806479 | D5: =K42 -> 268.89187 | E5: =C5*D5 -> 75.463939 | J5: Total Bet: | K5: 20 | M5: Total Bet: | N5: 2000 | P5: Total Bet: | Q5: 2000
B6: Total | C6: =SUM(C4:C5) -> 0.9698865 | J6: Simulated Game Total RTP: | K6: 0.9698864 | M6: Simulated Game Total RTP: | N6: 0.9708362 | P6: Simulated Game Total RTP: | Q6: 0.9710962
J7: Simulated Base Game Total RTP: | K7: 0.6892386 | M7: Simulated Base Game Total RTP: | N7: 0.0213131 | P7: Simulated Base Game Total RTP: | Q7: 0.0213002
J8: Simulated Base Game1 Total RTP: | K8: 0.011246 | M8: Simulated Base Game1 Total RTP: | N8: 0.0001881 | P8: Simulated Base Game1 Total RTP: | Q8: 0.0001956
B9: Hit Frequency | C9: =K30 -> 0.316018 | J9: Simulated Base Game2 Total RTP: | K9: 0.0328683 | M9: Simulated Base Game2 Total RTP: | N9: 0 | P9: Simulated Base Game2 Total RTP: | Q9: 0
B10: Max Exposure | C10: =K40 -> 1009091 | D10: Credits | E10: with Bet | F10: =K5 -> 20 | G10: Credits | J10: Simulated Base Game3 Total RTP: | K10: 0.0155376 | M10: Simulated Base Game3 Total RTP: | N10: 0 | P10: Simulated Base Game3 Total RTP: | Q10: 0
B11: Probability of Max Exposure | E11: 1 | F11: in | G11: 1000000000 | J11: Simulated Base Game4 Total RTP: | K11: 0.2582858 | M11: Simulated Base Game4 Total RTP: | N11: 0 | P11: Simulated Base Game4 Total RTP: | Q11: 0
B12: SD | C12: =K56/1.96 -> 16.802388 | J12: Simulated Base Game5 Total RTP: | K12: 0.0935276 | M12: Simulated Base Game5 Total RTP: | N12: 0 | P12: Simulated Base Game5 Total RTP: | Q12: 0
J13: Simulated Base Game6 Total RTP: | K13: 0.0223597 | M13: Simulated Base Game6 Total RTP: | N13: 0.0211249 | P13: Simulated Base Game6 Total RTP: | Q13: 0.0211046
J14: Simulated Base Game7 Total RTP: | K14: 0.030402 | M14: Simulated Base Game7 Total RTP: | N14: 0 | P14: Simulated Base Game7 Total RTP: | Q14: 0
C15: FG1 | D15: FG2 | J15: Simulated Base Game8 Total RTP: | K15: 0.0189418 | M15: Simulated Base Game8 Total RTP: | N15: 0 | P15: Simulated Base Game8 Total RTP: | Q15: 0
B16: Buy Bet | C16: 100 | D16: 100 | E16: x Total Bet | J16: Simulated Base Game9 Total RTP: | K16: 0.2060698 | M16: Simulated Base Game9 Total RTP: | N16: 0 | P16: Simulated Base Game9 Total RTP: | Q16: 0
B17: EV | C17: =C18*C16 -> 97.08362 | D17: =D18*D16 -> 97.10962 | J17: Simulated Free Game Total RTP: | K17: 0.2806479 | M17: Simulated Free Game Total RTP: | N17: 0.9495232 | P17: Simulated Free Game Total RTP: | Q17: 0.949796
B18: Total RTP | C18: =N6 -> 0.9708362 | D18: =Q6 -> 0.9710962 | J18: Simulated Individual Free Game Total RTP: | K18: 6.0995762 | M18: Simulated Individual Free Game Total RTP: | N18: 0.0587642 | P18: Simulated Individual Free Game Total RTP: | Q18: 0.1105669
B19: Hit Frequency | C19: =N30 -> 0.9999702 | D19: =Q30 -> 0.9741966
B20: SD | C20: =N56/1.96 -> 1.6184133 | D20: =Q56/1.96 -> 3.7108163 | J20: Simulated Base Game1 Individual RTP: | K20: 1.8303199 | M20: Simulated Base Game1 Individual RTP: | N20: 0.0064882 | P20: Simulated Base Game1 Individual RTP: | Q20: 0.0067452
B21: Max Exposure | C21: =N40 -> 487402 | D21: =Q40 -> 1674912 | J21: Simulated Base Game2 Individual RTP: | K21: 2.4598205 | M21: Simulated Base Game2 Individual RTP: | N21: NaN | P21: Simulated Base Game2 Individual RTP: | Q21: NaN
J22: Simulated Base Game3 Individual RTP: | K22: 0.9689961 | M22: Simulated Base Game3 Individual RTP: | N22: NaN | P22: Simulated Base Game3 Individual RTP: | Q22: NaN
J23: Simulated Base Game4 Individual RTP: | K23: 0.4831067 | M23: Simulated Base Game4 Individual RTP: | N23: NaN | P23: Simulated Base Game4 Individual RTP: | Q23: NaN
J24: Simulated Base Game5 Individual RTP: | K24: 0.7366079 | M24: Simulated Base Game5 Individual RTP: | N24: NaN | P24: Simulated Base Game5 Individual RTP: | Q24: NaN
J25: Simulated Base Game6 Individual RTP: | K25: 2.5360732 | M25: Simulated Base Game6 Individual RTP: | N25: 0.0217558 | P25: Simulated Base Game6 Individual RTP: | Q25: 0.0217349
J26: Simulated Base Game7 Individual RTP: | K26: 2.2751612 | M26: Simulated Base Game7 Individual RTP: | N26: NaN | P26: Simulated Base Game7 Individual RTP: | Q26: NaN
J27: Simulated Base Game8 Individual RTP: | K27: 1.4177312 | M27: Simulated Base Game8 Individual RTP: | N27: NaN | P27: Simulated Base Game8 Individual RTP: | Q27: NaN
J28: Simulated Base Game9 Individual RTP: | K28: 0.7708924 | M28: Simulated Base Game9 Individual RTP: | N28: NaN | P28: Simulated Base Game9 Individual RTP: | Q28: NaN
J30: MLHF: | K30: 0.316018 | M30: MLHF: | N30: 0.9999702 | P30: MLHF: | Q30: 0.9741966
J31: MLHF from BG1: | K31: 0.3236446 | M31: MLHF from BG1: | N31: 0.2083966 | P31: MLHF from BG1: | Q31: 0.2081146
J32: MLHF from BG2: | K32: 0.3026435 | M32: MLHF from BG2: | N32: NaN | P32: MLHF from BG2: | Q32: NaN
J33: MLHF from BG3: | K33: 0.2814397 | M33: MLHF from BG3: | N33: NaN | P33: MLHF from BG3: | Q33: NaN
J34: MLHF from BG4: | K34: 0.3271883 | M34: MLHF from BG4: | N34: NaN | P34: MLHF from BG4: | Q34: NaN
J35: MLHF from BG5: | K35: 0.2676874 | M35: MLHF from BG5: | N35: NaN | P35: MLHF from BG5: | Q35: NaN
J36: MLHF from BG6: | K36: 0.4372174 | M36: MLHF from BG6: | N36: 0.4189351 | P36: MLHF from BG6: | Q36: 0.4192757
J37: MLHF from BG7: | K37: 0.458768 | M37: MLHF from BG7: | N37: NaN | P37: MLHF from BG7: | Q37: NaN
J38: MLHF from BG8: | K38: 0.3038513 | M38: MLHF from BG8: | N38: NaN | P38: MLHF from BG8: | Q38: NaN
J39: MLHF from BG9: | K39: 0.3007236 | M39: MLHF from BG9: | N39: NaN | P39: MLHF from BG9: | Q39: NaN
J40: Max Liability: | K40: 1009091 | M40: Max Liability: | N40: 487402 | P40: Max Liability: | Q40: 1674912
J42: FG Triggering Odds: | K42: 268.89187 | M42: FG Triggering Odds: | N42: 1 | P42: FG Triggering Odds: | Q42: 1
...

Sheet BG Calc
C2: ='BG1 Reel'!AS9 -> R1 | D2: ='BG1 Reel'!AT9 -> R2 | E2: ='BG1 Reel'!AU9 -> R3 | F2: ='BG1 Reel'!AV9 -> R4 | G2: ='BG1 Reel'!AW9 -> R5 | H2: ='BG1 Reel'!AX9 -> R6 | K2: ='BG1 Reel'!R9 -> R1 | L2: ='BG1 Reel'!S9 -> R2 | M2: ='BG1 Reel'!T9 -> R3 | N2: ='BG1 Reel'!U9 -> R4 | O2: ='BG1 Reel'!V9 -> R5 | P2: ='BG1 Reel'!W9 -> R6 | S2: 6 | T2: 5 | U2: 4 | V2: 3 | Z2: Wild Multiplier | AA2: Weight | AE2: BG Type | AF2: Weight
B3: ='BG1 Reel'!AR10 -> WC | C3: ='BG1 Reel'!AS10 -> 0 | D3: ='BG1 Reel'!AT10 -> 4 | E3: ='BG1 Reel'!AU10 -> 8 | F3: ='BG1 Reel'!AV10 -> 2 | G3: ='BG1 Reel'!AW10 -> 2 | H3: ='BG1 Reel'!AX10 -> 0 | J3: ='BG1 Reel'!Q10 -> WC | K3: ='BG1 Reel'!R10 -> 0 | L3: ='BG1 Reel'!S10 -> 2 | M3: ='BG1 Reel'!T10 -> 4 | N3: ='BG1 Reel'!U10 -> 1 | O3: ='BG1 Reel'!V10 -> 1 | P3: ='BG1 Reel'!W10 -> 0 | R3: ='BG1 Reel'!Q10 -> WC | S3: 0 | T3: 0 | U3: 0 | V3: 0 | Z3: 1 | AA3: 10 | AC3: 56.67311 | AE3: BG1 | AF3: 23 | AG3: 1.8304736 | AH3: =1/AC3 -> 0.017645052
B4: ='BG1 Reel'!AR11 -> AA | C4: ='BG1 Reel'!AS11 -> 18 | D4: ='BG1 Reel'!AT11 -> 16 | E4: ='BG1 Reel'!AU11 -> 18 | F4: ='BG1 Reel'!AV11 -> 22 | G4: ='BG1 Reel'!AW11 -> 10 | H4: ='BG1 Reel'!AX11 -> 10 | J4: ='BG1 Reel'!Q11 -> AA | K4: ='BG1 Reel'!R11 -> 9 | L4: ='BG1 Reel'!S11 -> 6 | M4: ='BG1 Reel'!T11 -> 5 | N4: ='BG1 Reel'!U11 -> 10 | O4: ='BG1 Reel'!V11 -> 4 | P4: ='BG1 Reel'!W11 -> 5 | R4: ='BG1 Reel'!Q11 -> AA | S4: 150 | T4: 60 | U4: 40 | V4: 15 | Z4: 2 | AA4: 5 | AC4: ∞ | AE4: BG2 | AF4: 50 | AG4: 2.4523377 | AH4: 0
B5: ='BG1 Reel'!AR12 -> BB | C5: ='BG1 Reel'!AS12 -> 8 | D5: ='BG1 Reel'!AT12 -> 22 | E5: ='BG1 Reel'!AU12 -> 18 | F5: ='BG1 Reel'!AV12 -> 10 | G5: ='BG1 Reel'!AW12 -> 12 | H5: ='BG1 Reel'!AX12 -> 18 | J5: ='BG1 Reel'!Q12 -> BB | K5: ='BG1 Reel'!R12 -> 4 | L5: ='BG1 Reel'!S12 -> 9 | M5: ='BG1 Reel'!T12 -> 5 | N5: ='BG1 Reel'!U12 -> 4 | O5: ='BG1 Reel'!V12 -> 5 | P5: ='BG1 Reel'!W12 -> 9 | R5: ='BG1 Reel'!Q12 -> BB | S5: 60 | T5: 30 | U5: 20 | V5: 10 | Z5: 3 | AA5: 2 | AC5: ∞ | AE5: BG3 | AF5: 60 | AG5: 0.967243 | AH5: 0
B6: ='BG1 Reel'!AR13 -> CC | C6: ='BG1 Reel'!AS13 -> 10 | D6: ='BG1 Reel'!AT13 -> 18 | E6: ='BG1 Reel'!AU13 -> 18 | F6: ='BG1 Reel'!AV13 -> 22 | G6: ='BG1 Reel'!AW13 -> 12 | H6: ='BG1 Reel'!AX13 -> 26 | J6: ='BG1 Reel'!Q13 -> CC | K6: ='BG1 Reel'!R13 -> 5 | L6: ='BG1 Reel'!S13 -> 7 | M6: ='BG1 Reel'!T13 -> 5 | N6: ='BG1 Reel'!U13 -> 10 | O6: ='BG1 Reel'!V13 -> 5 | P6: ='BG1 Reel'!W13 -> 13 | R6: ='BG1 Reel'!Q13 -> CC | S6: 40 | T6: 20 | U6: 15 | V6: 7 | AC6: ∞ | AE6: BG4 | AF6: 2000 | AG6: 0.483145 | AH6: 0
B7: ='BG1 Reel'!AR14 -> DD | C7: ='BG1 Reel'!AS14 -> 18 | D7: ='BG1 Reel'!AT14 -> 8 | E7: ='BG1 Reel'!AU14 -> 10 | F7: ='BG1 Reel'!AV14 -> 4 | G7: ='BG1 Reel'!AW14 -> 4 | H7: ='BG1 Reel'!AX14 -> 20 | J7: ='BG1 Reel'!Q14 -> DD | K7: ='BG1 Reel'!R14 -> 9 | L7: ='BG1 Reel'!S14 -> 2 | M7: ='BG1 Reel'!T14 -> 1 | N7: ='BG1 Reel'!U14 -> 1 | O7: ='BG1 Reel'!V14 -> 1 | P7: ='BG1 Reel'!W14 -> 10 | R7: ='BG1 Reel'!Q14 -> DD | S7: 30 | T7: 15 | U7: 10 | V7: 4 | AC7: ∞ | AE7: BG5 | AF7: 475 | AG7: 0.7359006 | AH7: 0
B8: ='BG1 Reel'!AR15 -> EE | C8: ='BG1 Reel'!AS15 -> 4 | D8: ='BG1 Reel'!AT15 -> 6 | E8: ='BG1 Reel'!AU15 -> 10 | F8: ='BG1 Reel'!AV15 -> 6 | G8: ='BG1 Reel'!AW15 -> 6 | H8: ='BG1 Reel'!AX15 -> 6 | J8: ='BG1 Reel'!Q15 -> EE | K8: ='BG1 Reel'!R15 -> 2 | L8: ='BG1 Reel'!S15 -> 1 | M8: ='BG1 Reel'!T15 -> 1 | N8: ='BG1 Reel'!U15 -> 2 | O8: ='BG1 Reel'!V15 -> 2 | P8: ='BG1 Reel'!W15 -> 3 | R8: ='BG1 Reel'!Q15 -> EE | S8: 30 | T8: 10 | U8: 8 | V8: 3 | AC8: 2.44167 | AE8: BG6 | AF8: 33 | AG8: 2.5320739 | AH8: =1/AC8 -> 0.40955575
B9: ='BG1 Reel'!AR16 -> FF | C9: ='BG1 Reel'!AS16 -> 22 | D9: ='BG1 Reel'!AT16 -> 12 | E9: ='BG1 Reel'!AU16 -> 10 | F9: ='BG1 Reel'!AV16 -> 4 | G9: ='BG1 Reel'!AW16 -> 4 | H9: ='BG1 Reel'!AX16 -> 20 | J9: ='BG1 Reel'!Q16 -> FF | K9: ='BG1 Reel'!R16 -> 11 | L9: ='BG1 Reel'!S16 -> 4 | M9: ='BG1 Reel'!T16 -> 1 | N9: ='BG1 Reel'!U16 -> 1 | O9: ='BG1 Reel'!V16 -> 1 | P9: ='BG1 Reel'!W16 -> 10 | R9: ='BG1 Reel'!Q16 -> FF | S9: 30 | T9: 10 | U9: 8 | V9: 3 | AC9: ∞ | AE9: BG7 | AF9: 50 | AG9: 2.2800107 | AH9: 0
B10: ='BG1 Reel'!AR17 -> GG | C10: ='BG1 Reel'!AS17 -> 14 | D10: ='BG1 Reel'!AT17 -> 18 | E10: ='BG1 Reel'!AU17 -> 18 | F10: ='BG1 Reel'!AV17 -> 22 | G10: ='BG1 Reel'!AW17 -> 10 | H10: ='BG1 Reel'!AX17 -> 18 | J10: ='BG1 Reel'!Q17 -> GG | K10: ='BG1 Reel'!R17 -> 7 | L10: ='BG1 Reel'!S17 -> 7 | M10: ='BG1 Reel'!T17 -> 5 | N10: ='BG1 Reel'!U17 -> 10 | O10: ='BG1 Reel'!V17 -> 4 | P10: ='BG1 Reel'!W17 -> 9 | R10: ='BG1 Reel'!Q17 -> GG | S10: 20 | T10: 6 | U10: 4 | V10: 2 | AC10: ∞ | AE10: BG8 | AF10: 50 | AG10: 1.4175439 | AH10: 0
B11: ='BG1 Reel'!AR18 -> HH | C11: ='BG1 Reel'!AS18 -> 2 | D11: ='BG1 Reel'!AT18 -> 6 | E11: ='BG1 Reel'!AU18 -> 10 | F11: ='BG1 Reel'!AV18 -> 4 | G11: ='BG1 Reel'!AW18 -> 4 | H11: ='BG1 Reel'!AX18 -> 2 | J11: ='BG1 Reel'!Q18 -> HH | K11: ='BG1 Reel'!R18 -> 1 | L11: ='BG1 Reel'!S18 -> 1 | M11: ='BG1 Reel'!T18 -> 1 | N11: ='BG1 Reel'!U18 -> 1 | O11: ='BG1 Reel'!V18 -> 1 | P11: ='BG1 Reel'!W18 -> 1 | R11: ='BG1 Reel'!Q18 -> HH | S11: 20 | T11: 6 | U11: 4 | V11: 2 | AC11: ∞ | AE11: BG9 | AF11: 1000 | AG11: 0.7710363 | AH11: 0
B12: ='BG1 Reel'!AR19 -> JJ | C12: ='BG1 Reel'!AS19 -> 14 | D12: ='BG1 Reel'!AT19 -> 14 | E12: ='BG1 Reel'!AU19 -> 16 | F12: ='BG1 Reel'!AV19 -> 12 | G12: ='BG1 Reel'!AW19 -> 10 | H12: ='BG1 Reel'!AX19 -> 10 | J12: ='BG1 Reel'!Q19 -> JJ | K12: ='BG1 Reel'!R19 -> 7 | L12: ='BG1 Reel'!S19 -> 5 | M12: ='BG1 Reel'!T19 -> 4 | N12: ='BG1 Reel'!U19 -> 5 | O12: ='BG1 Reel'!V19 -> 4 | P12: ='BG1 Reel'!W19 -> 5 | R12: ='BG1 Reel'!Q19 -> JJ | S12: 20 | T12: 6 | U12: 4 | V12: 2 | AG12: =SUMPRODUCT(BG_Reel_Weight,AG3:AG11)/SUM(BG_Reel_Weight) -> 0.68913863 | AH12: =SUMPRODUCT(BG_Reel_Weight,AH3:AH11)/SUM(BG_Reel_Weight) -> 0.0037212446
B13: ='BG1 Reel'!AR20 -> KK | C13: ='BG1 Reel'!AS20 -> 14 | D13: ='BG1 Reel'!AT20 -> 20 | E13: ='BG1 Reel'!AU20 -> 20 | F13: ='BG1 Reel'!AV20 -> 12 | G13: ='BG1 Reel'!AW20 -> 12 | H13: ='BG1 Reel'!AX20 -> 18 | J13: ='BG1 Reel'!Q20 -> KK | K13: ='BG1 Reel'!R20 -> 7 | L13: ='BG1 Reel'!S20 -> 8 | M13: ='BG1 Reel'!T20 -> 6 | N13: ='BG1 Reel'!U20 -> 5 | O13: ='BG1 Reel'!V20 -> 5 | P13: ='BG1 Reel'!W20 -> 9 | R13: ='BG1 Reel'!Q20 -> KK | S13: 10 | T13: 4 | U13: 2 | V13: 1 | AG13: =Summary!E5/'BG Calc'!AH13 -> 0.28081978 | AH13: =1/AH12 -> 268.72729
B14: ='BG1 Reel'!AR21 -> LL | C14: ='BG1 Reel'!AS21 -> 14 | D14: ='BG1 Reel'!AT21 -> 22 | E14: ='BG1 Reel'!AU21 -> 18 | F14: ='BG1 Reel'!AV21 -> 18 | G14: ='BG1 Reel'!AW21 -> 10 | H14: ='BG1 Reel'!AX21 -> 14 | J14: ='BG1 Reel'!Q21 -> LL | K14: ='BG1 Reel'!R21 -> 7 | L14: ='BG1 Reel'!S21 -> 9 | M14: ='BG1 Reel'!T21 -> 5 | N14: ='BG1 Reel'!U21 -> 8 | O14: ='BG1 Reel'!V21 -> 4 | P14: ='BG1 Reel'!W21 -> 7 | R14: ='BG1 Reel'!Q21 -> LL | S14: 10 | T14: 4 | U14: 2 | V14: 1 | AG14: =SUM(AG12:AG13) -> 0.9699584
B15: ='BG1 Reel'!AR22 -> BN | C15: ='BG1 Reel'!AS22 -> 8 | D15: ='BG1 Reel'!AT22 -> 2 | E15: ='BG1 Reel'!AU22 -> 2 | F15: ='BG1 Reel'!AV22 -> 2 | G15: ='BG1 Reel'!AW22 -> 2 | H15: ='BG1 Reel'!AX22 -> 4 | J15: ='BG1 Reel'!Q22 -> BN | K15: ='BG1 Reel'!R22 -> 4 | L15: ='BG1 Reel'!S22 -> 1 | M15: ='BG1 Reel'!T22 -> 1 | N15: ='BG1 Reel'!U22 -> 1 | O15: ='BG1 Reel'!V22 -> 1 | P15: ='BG1 Reel'!W22 -> 2 | R15: ='BG1 Reel'!Q22 -> BN | S15: 0 | T15: 0 | U15: 0 | V15: 0
B16: ='BG1 Reel'!AR23 -> WC-0 | C16: ='BG1 Reel'!AS23 -> 73 | D16: ='BG1 Reel'!AT23 -> 58 | E16: ='BG1 Reel'!AU23 -> 36 | F16: ='BG1 Reel'!AV23 -> 57 | G16: ='BG1 Reel'!AW23 -> 36 | H16: ='BG1 Reel'!AX23 -> 83 | J16: Total | K16: =SUM(K3:K15) -> 73 | L16: =SUM(L3:L15) -> 62 | M16: =SUM(M3:M15) -> 44 | N16: =SUM(N3:N15) -> 59 | O16: =SUM(O3:O15) -> 38 | P16: =SUM(P3:P15) -> 83
B17: ='BG1 Reel'!AR24 -> AA-0 | C17: ='BG1 Reel'!AS24 -> 57 | D17: ='BG1 Reel'!AT24 -> 48 | E17: ='BG1 Reel'!AU24 -> 30 | F17: ='BG1 Reel'!AV24 -> 39 | G17: ='BG1 Reel'!AW24 -> 30 | H17: ='BG1 Reel'!AX24 -> 75 | J17: Cycle | K17: =PRODUCT(K16:P16) -> 37057910384 | Z17: #PttrnNum | AA17: Pattern | AG17: BGWeights | AK17: BaseGame
B18: ='BG1 Reel'!AR25 -> BB-0 | C18: ='BG1 Reel'!AS25 -> 67 | D18: ='BG1 Reel'!AT25 -> 43 | E18: ='BG1 Reel'!AU25 -> 28 | F18: ='BG1 Reel'!AV25 -> 52 | G18: ='BG1 Reel'!AW25 -> 28 | H18: ='BG1 Reel'!AX25 -> 67 | Z18: 1 | AA18: 0 | AB18: 0 | AC18: 0 | AD18: 0 | AE18: 1 | AF18: 1 | AG18: 200 | AK18: Weights
B19: ='BG1 Reel'!AR26 -> CC-0 | C19: ='BG1 Reel'!AS26 -> 65 | D19: ='BG1 Reel'!AT26 -> 46 | E19: ='BG1 Reel'!AU26 -> 28 | F19: ='BG1 Reel'!AV26 -> 40 | G19: ='BG1 Reel'!AW26 -> 29 | H19: ='BG1 Reel'!AX26 -> 60 | J19: Bet | K19: 20 | Z19: 2 | AA19: 0 | AB19: 0 | AC19: 0 | AD19: 1 | AE19: 0 | AF19: 1 | AG19: 200 | AJ19: NumRows | AK19: Opt0 | AL19: Opt1
B20: ='BG1 Reel'!AR27 -> DD-0 | C20: ='BG1 Reel'!AS27 -> 57 | D20: ='BG1 Reel'!AT27 -> 55 | E20: ='BG1 Reel'!AU27 -> 36 | F20: ='BG1 Reel'!AV27 -> 55 | G20: ='BG1 Reel'!AW27 -> 35 | H20: ='BG1 Reel'!AX27 -> 65 | J20: RTP | K20: =R86/(K19*K17) -> 0.072519772 | Z20: 3 | AA20: 0 | AB20: 0 | AC20: 1 | AD20: 0 | AE20: 0 | AF20: 1 | AG20: 10 | AJ20: 2 | AK20: 100 | AL20: 25
B21: ='BG1 Reel'!AR28 -> EE-0 | C21: ='BG1 Reel'!AS28 -> 69 | D21: ='BG1 Reel'!AT28 -> 56 | E21: ='BG1 Reel'!AU28 -> 34 | F21: ='BG1 Reel'!AV28 -> 53 | G21: ='BG1 Reel'!AW28 -> 32 | H21: ='BG1 Reel'!AX28 -> 77 | J21: Trigger Rate | K21: =K17/SUM(N88:N132) -> 412.2041 | Z21: 4 | AA21: 0 | AB21: 1 | AC21: 0 | AD21: 0 | AE21: 0 | AF21: 1 | AG21: 10 | AJ21: 3 | AK21: 200 | AL21: 75
B22: ='BG1 Reel'!AR29 -> FF-0 | C22: ='BG1 Reel'!AS29 -> 53 | D22: ='BG1 Reel'!AT29 -> 52 | E22: ='BG1 Reel'!AU29 -> 34 | F22: ='BG1 Reel'!AV29 -> 56 | G22: ='BG1 Reel'!AW29 -> 34 | H22: ='BG1 Reel'!AX29 -> 65 | Z22: 5 | AA22: 1 | AB22: 0 | AC22: 0 | AD22: 0 | AE22: 0 | AF22: 1 | AG22: 10 | AJ22: 4 | AK22: 75 | AL22: 75
B23: ='BG1 Reel'!AR30 -> GG-0 | C23: ='BG1 Reel'!AS30 -> 62 | D23: ='BG1 Reel'!AT30 -> 47 | E23: ='BG1 Reel'!AU30 -> 29 | F23: ='BG1 Reel'!AV30 -> 39 | G23: ='BG1 Reel'!AW30 -> 30 | H23: ='BG1 Reel'!AX30 -> 67 | J23: State | K23: 222222 | Z23: 6 | AA23: 0 | AB23: 0 | AC23: 0 | AD23: 1 | AE23: 1 | AF23: 0 | AG23: 200 | AJ23: 5 | AK23: 50 | AL23: 75
B24: ='BG1 Reel'!AR31 -> HH-0 | C24: ='BG1 Reel'!AS31 -> 71 | D24: ='BG1 Reel'!AT31 -> 56 | E24: ='BG1 Reel'!AU31 -> 34 | F24: ='BG1 Reel'!AV31 -> 55 | G24: ='BG1 Reel'!AW31 -> 34 | H24: ='BG1 Reel'!AX31 -> 81 | Z24: 7 | AA24: 0 | AB24: 0 | AC24: 1 | AD24: 0 | AE24: 1 | AF24: 0 | AG24: 200 | AJ24: 6 | AK24: 15 | AL24: 75
B25: ='BG1 Reel'!AR32 -> JJ-0 | C25: ='BG1 Reel'!AS32 -> 62 | D25: ='BG1 Reel'!AT32 -> 50 | E25: ='BG1 Reel'!AU32 -> 31 | F25: ='BG1 Reel'!AV32 -> 49 | G25: ='BG1 Reel'!AW32 -> 30 | H25: ='BG1 Reel'!AX32 -> 75 | K25: R1 | L25: R2 | M25: R3 | N25: R4 | O25: R5 | P25: R6 | Z25: 8 | AA25: 0 | AB25: 1 | AC25: 0 | AD25: 0 | AE25: 1 | AF25: 0 | AG25: 10 | AJ25: 7 | AK25: 10 | AL25: 75
B26: ='BG1 Reel'!AR33 -> KK-0 | C26: ='BG1 Reel'!AS33 -> 61 | D26: ='BG1 Reel'!AT33 -> 44 | E26: ='BG1 Reel'!AU33 -> 29 | F26: ='BG1 Reel'!AV33 -> 50 | G26: ='BG1 Reel'!AW33 -> 28 | H26: ='BG1 Reel'!AX33 -> 67 | J26: #Rows | K26: =VALUE(MID($K$23,RIGHT(K25,1),1)) -> 2 | L26: =VALUE(MID($K$23,RIGHT(L25,1),1)) -> 2 | M26: =VALUE(MID($K$23,RIGHT(M25,1),1)) -> 2 | N26: =VALUE(MID($K$23,RIGHT(N25,1),1)) -> 2 | O26: =VALUE(MID($K$23,RIGHT(O25,1),1)) -> 2 | P26: =VALUE(MID($K$23,RIGHT(P25,1),1)) -> 2 | Z26: 9 | AA26: 1 | AB26: 0 | AC26: 0 | AD26: 0 | AE26: 1 | AF26: 0 | AG26: 10
B27: ='BG1 Reel'!AR34 -> LL-0 | C27: ='BG1 Reel'!AS34 -> 61 | D27: ='BG1 Reel'!AT34 -> 43 | E27: ='BG1 Reel'!AU34 -> 30 | F27: ='BG1 Reel'!AV34 -> 43 | G27: ='BG1 Reel'!AW34 -> 30 | H27: ='BG1 Reel'!AX34 -> 71 | Z27: 10 | AA27: 0 | AB27: 0 | AC27: 1 | AD27: 1 | AE27: 0 | AF27: 0 | AG27: 200
B28: ='BG1 Reel'!AR35 -> BN-0 | C28: ='BG1 Reel'!AS35 -> 65 | D28: ='BG1 Reel'!AT35 -> 60 | E28: ='BG1 Reel'!AU35 -> 42 | F28: ='BG1 Reel'!AV35 -> 57 | G28: ='BG1 Reel'!AW35 -> 36 | H28: ='BG1 Reel'!AX35 -> 79 | Z28: 11 | AA28: 0 | AB28: 1 | AC28: 0 | AD28: 1 | AE28: 0 | AF28: 0 | AG28: 200
B29: --- | C29: =K16 -> 73 | D29: =L16 -> 62 | E29: =M16 -> 44 | F29: =N16 -> 59 | G29: =O16 -> 38 | H29: =P16 -> 83 | Z29: 12 | AA29: 1 | AB29: 0 | AC29: 0 | AD29: 1 | AE29: 0 | AF29: 0 | AG29: 200
Z30: 13 | AA30: 0 | AB30: 1 | AC30: 1 | AD30: 0 | AE30: 0 | AF30: 0 | AG30: 200
B31: R1 | C31: R2 | D31: R3 | E31: R4 | F31: R5 | G31: R6 | H31: R1 | I31: R2 | J31: R3 | K31: R4 | L31: R5 | M31: R6 | N31: Hits | Q31: Pays | R31: Total Pays | Z31: 14 | AA31: 1 | AB31: 0 | AC31: 1 | AD31: 0 | AE31: 0 | AF31: 0 | AG31: 200
B32: =$B$4 -> AA | C32: =$B32 -> AA | D32: =$B32 -> AA | E32: =$B32 -> AA | F32: =$B32 -> AA | G32: =$B32 -> AA | H32: =SUMIF($B$3:$B$29,B32,C$3:C$29) -> 18 | I32: =SUMIF($B$3:$B$29,C32,D$3:D$29) -> 16 | J32: =SUMIF($B$3:$B$29,D32,E$3:E$29) -> 18 | K32: =SUMIF($B$3:$B$29,E32,F$3:F$29) -> 22 | L32: =SUMIF($B$3:$B$29,F32,G$3:G$29) -> 10 | M32: =SUMIF($B$3:$B$29,G32,H$3:H$29) -> 10 | N32: =PRODUCT(H32:M32) -> 11404800 | O32: 6 | P32: =B32 -> AA | Q32: =INDEX($S$3:$V$15,MATCH(P32,$R$3:$R$15,0),MATCH(O32,$S$2:$V$2,0)) -> 150 | R32: =Q32*N32 -> 1710720000 | Z32: 15 | AA32: 1 | AB32: 1 | AC32: 0 | AD32: 0 | AE32: 0 | AF32: 0 | AG32: 200
B33: =$B32 -> AA | C33: =$B32 -> AA | D33: =$B32 -> AA | E33: =$B32 -> AA | F33: =$B32 -> AA | G33: =F33&"-0" -> AA-0 | H33: =SUMIF($B$3:$B$29,B33,C$3:C$29) -> 18 | I33: =SUMIF($B$3:$B$29,C33,D$3:D$29) -> 16 | J33: =SUMIF($B$3:$B$29,D33,E$3:E$29) -> 18 | K33: =SUMIF($B$3:$B$29,E33,F$3:F$29) -> 22 | L33: =SUMIF($B$3:$B$29,F33,G$3:G$29) -> 10 | M33: =SUMIF($B$3:$B$29,G33,H$3:H$29) -> 75 | N33: =PRODUCT(H33:M33) -> 85536000 | O33: 5 | P33: =B33 -> AA | Q33: =INDEX($S$3:$V$15,MATCH(P33,$R$3:$R$15,0),MATCH(O33,$S$2:$V$2,0)) -> 60 | R33: =Q33*N33 -> 5132160000 | Z33: 16 | AA33: 0 | AB33: 0 | AC33: 0 | AD33: 1 | AE33: 1 | AF33: 1 | AG33: 500
B34: =$B32 -> AA | C34: =$B32 -> AA | D34: =$B32 -> AA | E34: =$B32 -> AA | F34: =E34&"-0" -> AA-0 | G34: =$B$29 -> --- | H34: =SUMIF($B$3:$B$29,B34,C$3:C$29) -> 18 | I34: =SUMIF($B$3:$B$29,C34,D$3:D$29) -> 16 | J34: =SUMIF($B$3:$B$29,D34,E$3:E$29) -> 18 | K34: =SUMIF($B$3:$B$29,E34,F$3:F$29) -> 22 | L34: =SUMIF($B$3:$B$29,F34,G$3:G$29) -> 30 | M34: =SUMIF($B$3:$B$29,G34,H$3:H$29) -> 83 | N34: =PRODUCT(H34:M34) -> 283979520 | O34: 4 | P34: =B34 -> AA | Q34: =INDEX($S$3:$V$15,MATCH(P34,$R$3:$R$15,0),MATCH(O34,$S$2:$V$2,0)) -> 40 | R34: =Q34*N34 -> 11359180800 | Z34: 17 | AA34: 0 | AB34: 0 | AC34: 1 | AD34: 0 | AE34: 1 | AF34: 1 | AG34: 500
B35: =$B33 -> AA | C35: =$B32 -> AA | D35: =$B32 -> AA | E35: =D35&"-0" -> AA-0 | F35: =$B$29 -> --- | G35: =$B$29 -> --- | H35: =SUMIF($B$3:$B$29,B35,C$3:C$29) -> 18 | I35: =SUMIF($B$3:$B$29,C35,D$3:D$29) -> 16 | J35: =SUMIF($B$3:$B$29,D35,E$3:E$29) -> 18 | K35: =SUMIF($B$3:$B$29,E35,F$3:F$29) -> 39 | L35: =SUMIF($B$3:$B$29,F35,G$3:G$29) -> 38 | M35: =SUMIF($B$3:$B$29,G35,H$3:H$29) -> 83 | N35: =PRODUCT(H35:M35) -> 637663104 | O35: 3 | P35: =B35 -> AA | Q35: =INDEX($S$3:$V$15,MATCH(P35,$R$3:$R$15,0),MATCH(O35,$S$2:$V$2,0)) -> 15 | R35: =Q35*N35 -> 9564946560 | Z35: 18 | AA35: 0 | AB35: 1 | AC35: 0 | AD35: 0 | AE35: 1 | AF35: 1 | AG35: 500
Z36: 19 | AA36: 1 | AB36: 0 | AC36: 0 | AD36: 0 | AE36: 1 | AF36: 1 | AG36: 500
B37: =$B$5 -> BB | C37: =$B37 -> BB | D37: =$B37 -> BB | E37: =$B37 -> BB | F37: =$B37 -> BB | G37: =$B37 -> BB | H37: =SUMIF($B$3:$B$29,B37,C$3:C$29) -> 8 | I37: =SUMIF($B$3:$B$29,C37,D$3:D$29) -> 22 | J37: =SUMIF($B$3:$B$29,D37,E$3:E$29) -> 18 | K37: =SUMIF($B$3:$B$29,E37,F$3:F$29) -> 10 | L37: =SUMIF($B$3:$B$29,F37,G$3:G$29) -> 12 | M37: =SUMIF($B$3:$B$29,G37,H$3:H$29) -> 18 | N37: =PRODUCT(H37:M37) -> 6842880 | O37: 6 | P37: =B37 -> BB | Q37: =INDEX($S$3:$V$15,MATCH(P37,$R$3:$R$15,0),MATCH(O37,$S$2:$V$2,0)) -> 60 | R37: =Q37*N37 -> 410572800 | Z37: 20 | AA37: 0 | AB37: 0 | AC37: 1 | AD37: 1 | AE37: 0 | AF37: 1 | AG37: 500
B38: =$B37 -> BB | C38: =$B37 -> BB | D38: =$B37 -> BB | E38: =$B37 -> BB | F38: =$B37 -> BB | G38: =F38&"-0" -> BB-0 | H38: =SUMIF($B$3:$B$29,B38,C$3:C$29) -> 8 | I38: =SUMIF($B$3:$B$29,C38,D$3:D$29) -> 22 | J38: =SUMIF($B$3:$B$29,D38,E$3:E$29) -> 18 | K38: =SUMIF($B$3:$B$29,E38,F$3:F$29) -> 10 | L38: =SUMIF($B$3:$B$29,F38,G$3:G$29) -> 12 | M38: =SUMIF($B$3:$B$29,G38,H$3:H$29) -> 67 | N38: =PRODUCT(H38:M38) -> 25470720 | O38: 5 | P38: =B38 -> BB | Q38: =INDEX($S$3:$V$15,MATCH(P38,$R$3:$R$15,0),MATCH(O38,$S$2:$V$2,0)) -> 30 | R38: =Q38*N38 -> 764121600 | Z38: 21 | AA38: 0 | AB38: 1 | AC38: 0 | AD38: 1 | AE38: 0 | AF38: 1 | AG38: 500
B39: =$B37 -> BB | C39: =$B37 -> BB | D39: =$B37 -> BB | E39: =$B37 -> BB | F39: =E39&"-0" -> BB-0 | G39: =$B$29 -> --- | H39: =SUMIF($B$3:$B$29,B39,C$3:C$29) -> 8 | I39: =SUMIF($B$3:$B$29,C39,D$3:D$29) -> 22 | J39: =SUMIF($B$3:$B$29,D39,E$3:E$29) -> 18 | K39: =SUMIF($B$3:$B$29,E39,F$3:F$29) -> 10 | L39: =SUMIF($B$3:$B$29,F39,G$3:G$29) -> 28 | M39: =SUMIF($B$3:$B$29,G39,H$3:H$29) -> 83 | N39: =PRODUCT(H39:M39) -> 73624320 | O39: 4 | P39: =B39 -> BB | Q39: =INDEX($S$3:$V$15,MATCH(P39,$R$3:$R$15,0),MATCH(O39,$S$2:$V$2,0)) -> 20 | R39: =Q39*N39 -> 1472486400 | Z39: 22 | AA39: 1 | AB39: 0 | AC39: 0 | AD39: 1 | AE39: 0 | AF39: 1 | AG39: 500
B40: =$B38 -> BB | C40: =$B37 -> BB | D40: =$B37 -> BB | E40: =D40&"-0" -> BB-0 | F40: =$B$29 -> --- | G40: =$B$29 -> --- | H40: =SUMIF($B$3:$B$29,B40,C$3:C$29) -> 8 | I40: =SUMIF($B$3:$B$29,C40,D$3:D$29) -> 22 | J40: =SUMIF($B$3:$B$29,D40,E$3:E$29) -> 18 | K40: =SUMIF($B$3:$B$29,E40,F$3:F$29) -> 52 | L40: =SUMIF($B$3:$B$29,F40,G$3:G$29) -> 38 | M40: =SUMIF($B$3:$B$29,G40,H$3:H$29) -> 83 | N40: =PRODUCT(H40:M40) -> 519577344 | O40: 3 | P40: =B40 -> BB | Q40: =INDEX($S$3:$V$15,MATCH(P40,$R$3:$R$15,0),MATCH(O40,$S$2:$V$2,0)) -> 10 | R40: =Q40*N40 -> 5195773440 | Z40: 23 | AA40: 0 | AB40: 1 | AC40: 1 | AD40: 0 | AE40: 0 | AF40: 1 | AG40: 500
Z41: 24 | AA41: 1 | AB41: 0 | AC41: 1 | AD41: 0 | AE41: 0 | AF41: 1 | AG41: 500
...

Sheet BG1 Reel
R2: R1 | S2: R2 | T2: R3 | U2: R4 | V2: R5 | W2: R6
B3: Position | C3: Reel 1 | D3: Reel 2 | E3: Reel 3 | F3: Reel 4 | G3: Reel 5 | H3: Reel 6 | J3: Reel 1 | K3: Reel 2 | L3: Reel 3 | M3: Reel 4 | N3: Reel 5 | O3: Reel 6 | Q3: #Rows | R3: ='BG Calc'!K26 -> 2 | S3: ='BG Calc'!L26 -> 2 | T3: ='BG Calc'!M26 -> 2 | U3: ='BG Calc'!N26 -> 2 | V3: ='BG Calc'!O26 -> 2 | W3: ='BG Calc'!P26 -> 2
B4: =B5-1 -> -6 | C4: =INDEX(C$10:C$223,COUNTA(C$10:C$223)+$B4+1,1) -> DD | D4: =INDEX(D$10:D$223,COUNTA(D$10:D$223)+$B4+1,1) -> BB | E4: =INDEX(E$10:E$223,COUNTA(E$10:E$223)+$B4+1,1) -> KK | F4: =INDEX(F$10:F$223,COUNTA(F$10:F$223)+$B4+1,1) -> AA | G4: =INDEX(G$10:G$223,COUNTA(G$10:G$223)+$B4+1,1) -> GG | H4: =INDEX(H$10:H$223,COUNTA(H$10:H$223)+$B4+1,1) -> CC | J4: =IF(C4="","",1) -> 1 | K4: =IF(D4="","",1) -> 1 | L4: =IF(E4="","",1) -> 1 | M4: =IF(F4="","",1) -> 1 | N4: =IF(G4="","",1) -> 1 | O4: =IF(H4="","",1) -> 1
B5: =B6-1 -> -5 | C5: =INDEX(C$10:C$223,COUNTA(C$10:C$223)+$B5+1,1) -> AA | D5: =INDEX(D$10:D$223,COUNTA(D$10:D$223)+$B5+1,1) -> LL | E5: =INDEX(E$10:E$223,COUNTA(E$10:E$223)+$B5+1,1) -> WC | F5: =INDEX(F$10:F$223,COUNTA(F$10:F$223)+$B5+1,1) -> LL | G5: =INDEX(G$10:G$223,COUNTA(G$10:G$223)+$B5+1,1) -> GG | H5: =INDEX(H$10:H$223,COUNTA(H$10:H$223)+$B5+1,1) -> GG | J5: =IF(C5="","",1) -> 1 | K5: =IF(D5="","",1) -> 1 | L5: =IF(E5="","",1) -> 1 | M5: =IF(F5="","",1) -> 1 | N5: =IF(G5="","",1) -> 1 | O5: =IF(H5="","",1) -> 1
B6: =B7-1 -> -4 | C6: =INDEX(C$10:C$223,COUNTA(C$10:C$223)+$B6+1,1) -> JJ | D6: =INDEX(D$10:D$223,COUNTA(D$10:D$223)+$B6+1,1) -> CC | E6: =INDEX(E$10:E$223,COUNTA(E$10:E$223)+$B6+1,1) -> LL | F6: =INDEX(F$10:F$223,COUNTA(F$10:F$223)+$B6+1,1) -> AA | G6: =INDEX(G$10:G$223,COUNTA(G$10:G$223)+$B6+1,1) -> KK | H6: =INDEX(H$10:H$223,COUNTA(H$10:H$223)+$B6+1,1) -> CC | J6: =IF(C6="","",1) -> 1 | K6: =IF(D6="","",1) -> 1 | L6: =IF(E6="","",1) -> 1 | M6: =IF(F6="","",1) -> 1 | N6: =IF(G6="","",1) -> 1 | O6: =IF(H6="","",1) -> 1
B7: =B8-1 -> -3 | C7: =INDEX(C$10:C$223,COUNTA(C$10:C$223)+$B7+1,1) -> FF | D7: =INDEX(D$10:D$223,COUNTA(D$10:D$223)+$B7+1,1) -> LL | E7: =INDEX(E$10:E$223,COUNTA(E$10:E$223)+$B7+1,1) -> CC | F7: =INDEX(F$10:F$223,COUNTA(F$10:F$223)+$B7+1,1) -> CC | G7: =INDEX(G$10:G$223,COUNTA(G$10:G$223)+$B7+1,1) -> EE | H7: =INDEX(H$10:H$223,COUNTA(H$10:H$223)+$B7+1,1) -> GG | J7: =IF(C7="","",1) -> 1 | K7: =IF(D7="","",1) -> 1 | L7: =IF(E7="","",1) -> 1 | M7: =IF(F7="","",1) -> 1 | N7: =IF(G7="","",1) -> 1 | O7: =IF(H7="","",1) -> 1
B8: =B9-1 -> -2 | C8: =INDEX(C$10:C$223,COUNTA(C$10:C$223)+$B8+1,1) -> LL | D8: =INDEX(D$10:D$223,COUNTA(D$10:D$223)+$B8+1,1) -> KK | E8: =INDEX(E$10:E$223,COUNTA(E$10:E$223)+$B8+1,1) -> AA | F8: =INDEX(F$10:F$223,COUNTA(F$10:F$223)+$B8+1,1) -> AA | G8: =INDEX(G$10:G$223,COUNTA(G$10:G$223)+$B8+1,1) -> BB | H8: =INDEX(H$10:H$223,COUNTA(H$10:H$223)+$B8+1,1) -> CC | J8: =IF(C8="","",1) -> 1 | K8: =IF(D8="","",1) -> 1 | L8: =IF(E8="","",1) -> 1 | M8: =IF(F8="","",1) -> 1 | N8: =IF(G8="","",1) -> 1 | O8: =IF(H8="","",1) -> 1
B9: =B10-1 -> -1 | C9: =INDEX(C$10:C$223,COUNTA(C$10:C$223)+$B9+1,1) -> DD | D9: =INDEX(D$10:D$223,COUNTA(D$10:D$223)+$B9+1,1) -> LL | E9: =INDEX(E$10:E$223,COUNTA(E$10:E$223)+$B9+1,1) -> WC | F9: =INDEX(F$10:F$223,COUNTA(F$10:F$223)+$B9+1,1) -> LL | G9: =INDEX(G$10:G$223,COUNTA(G$10:G$223)+$B9+1,1) -> CC | H9: =INDEX(H$10:H$223,COUNTA(H$10:H$223)+$B9+1,1) -> KK | J9: =IF(C9="","",1) -> 1 | K9: =IF(D9="","",1) -> 1 | L9: =IF(E9="","",1) -> 1 | M9: =IF(F9="","",1) -> 1 | N9: =IF(G9="","",1) -> 1 | O9: =IF(H9="","",1) -> 1 | R9: R1 | S9: R2 | T9: R3 | U9: R4 | V9: R5 | W9: R6 | Y9: 1 | Z9: WC | AB9: R1 | AC9: R2 | AD9: R3 | AE9: R4 | AF9: R5 | AG9: R6 | AK9: R1 | AL9: R2 | AM9: R3 | AN9: R4 | AO9: R5 | AP9: R6 | AS9: R1 | AT9: R2 | AU9: R3 | AV9: R4 | AW9: R5 | AX9: R6
B10: 0 | C10: BB | D10: FF | E10: JJ | F10: BB | G10: JJ | H10: HH | J10: =IF(C10="","",1) -> 1 | K10: =IF(D10="","",1) -> 1 | L10: =IF(E10="","",1) -> 1 | M10: =IF(F10="","",1) -> 1 | N10: =IF(G10="","",1) -> 1 | O10: =IF(H10="","",1) -> 1 | Q10: =Z9 -> WC | R10: =COUNTIF(C$10:C$135,$Q10) -> 0 | S10: =COUNTIF(D$10:D$135,$Q10) -> 2 | T10: =COUNTIF(E$10:E$135,$Q10) -> 4 | U10: =COUNTIF(F$10:F$135,$Q10) -> 1 | V10: =COUNTIF(G$10:G$135,$Q10) -> 1 | W10: =COUNTIF(H$10:H$135,$Q10) -> 0 | Y10: =Y9+1 -> 2 | Z10: AA | AB10: =IF(R$3=2,IF(COUNTA(C9:C10) = R$3,COUNTIF(C9:C10, $Z$9) & COUNTIF(C9:C10, $Z$9)+COUNTIF(C9:C10, $Z$10) & COUNTIF(C9:C10, $Z$9)+COUNTIF(C9:C10, $Z$11) & COUNTIF(C9:C10, $Z$9)+COUNTIF(C9:C10, $Z$12) & COUNTIF(C9:C10, $Z$9)+COUNTIF(C9:C10, $Z$13) & COUNTIF(C9:C10, $Z$9)+COUNTIF(C9:C10, $Z$14) & COUNTIF(C9:C10, $Z$9)+COUNTIF(C9:C10, $Z$15) & COUNTIF(C9:C10, $Z$9)+COUNTIF(C9:C10, $Z$16) & COUNTIF(C9:C10, $Z$9)+COUNTIF(C9:C10, $Z$17) & COUNTIF(C9:C10, $Z$9)+COUNTIF(C9:C10, $Z$18) & COUNTIF(C9:C10, $Z$9)+COUNTIF(C9:C10, $Z$19) & COUNTIF(C9:C10, $Z$9)+COUNTIF(C9:C10, $Z$20) & COUNTIF(C9:C10, $Z$21),""), IF(R$3=3,IF(COUNTA(C8:C10) = R$3,COUNTIF(C8:C10, $Z$9) & COUNTIF(C8:C10, $Z$9)+COUNTIF(C8:C10, $Z$10) & COUNTIF(C8:C10, $Z$9)+COUNTIF(C8:C10, $Z$11) & COUNTIF(C8:C10, $Z$9)+COUNTIF(C8:C10, $Z$12) & COUNTIF(C8:C10, $Z$9)+COUNTIF(C8:C10, $Z$13) & COUNTIF(C8:C10, $Z$9)+COUNTIF(C8:C10, $Z$14) & COUNTIF(C8:C10, $Z$9)+COUNTIF(C8:C10, $Z$15) & COUNTIF(C8:C10, $Z$9)+COUNTIF(C8:C10, $Z$16) & COUNTIF(C8:C10, $Z$9)+COUNTIF(C8:C10, $Z$17) & COUNTIF(C8:C10, $Z$9)+COUNTIF(C8:C10, $Z$18) & COUNTIF(C8:C10, $Z$9)+COUNTIF(C8:C10, $Z$19) & COUNTIF(C8:C10, $Z$9)+COUNTIF(C8:C10, $Z$20) & COUNTIF(C8:C10, $Z$21),""), IF(R$3=4,IF(COUNTA(C7:C10) = R$3,COUNTIF(C7:C10, $Z$9) & COUNTIF(C7:C10, $Z$9)+COUNTIF(C7:C10, $Z$10) & COUNTIF(C7:C10, $Z$9)+COUNTIF(C7:C10, $Z$11) & COUNTIF(C7:C10, $Z$9)+COUNTIF(C7:C10, $Z$12) & COUNTIF(C7:C10, $Z$9)+COUNTIF(C7:C10, $Z$13) & COUNTIF(C7:C10, $Z$9)+COUNTIF(C7:C10, $Z$14) & COUNTIF(C7:C10, $Z$9)+COUNTIF(C7:C10, $Z$15) & COUNTIF(C7:C10, $Z$9)+COUNTIF(C7:C10, $Z$16) & COUNTIF(C7:C10, $Z$9)+COUNTIF(C7:C10, $Z$17) & COUNTIF(C7:C10, $Z$9)+COUNTIF(C7:C10, $Z$18) & COUNTIF(C7:C10, $Z$9)+COUNTIF(C7:C10, $Z$19) & COUNTIF(C7:C10, $Z$9)+COUNTIF(C7:C10, $Z$20) & COUNTIF(C7:C10, $Z$21),""), IF(R$3=5,IF(COUNTA(C6:C10) = R$3,COUNTIF(C6:C10, $Z$9) & COUNTIF(C6:C10, $Z$9)+COUNTIF(C6:C10, $Z$10) & COUNTIF(C6:C10, $Z$9)+COUNTIF(C6:C10, $Z$11) & COUNTIF(C6:C10, $Z$9)+COUNTIF(C6:C10, $Z$12) & COUNTIF(C6:C10, $Z$9)+COUNTIF(C6:C10, $Z$13) & COUNTIF(C6:C10, $Z$9)+COUNTIF(C6:C10, $Z$14) & COUNTIF(C6:C10, $Z$9)+COUNTIF(C6:C10, $Z$15) & COUNTIF(C6:C10, $Z$9)+COUNTIF(C6:C10, $Z$16) & COUNTIF(C6:C10, $Z$9)+COUNTIF(C6:C10, $Z$17) & COUNTIF(C6:C10, $Z$9)+COUNTIF(C6:C10, $Z$18) & COUNTIF(C6:C10, $Z$9)+COUNTIF(C6:C10, $Z$19) & COUNTIF(C6:C10, $Z$9)+COUNTIF(C6:C10, $Z$20) & COUNTIF(C6:C10, $Z$21),""), IF(R$3=6,IF(COUNTA(C5:C10) = R$3,COUNTIF(C5:C10, $Z$9) & COUNTIF(C5:C10, $Z$9)+COUNTIF(C5:C10, $Z$10) & COUNTIF(C5:C10, $Z$9)+COUNTIF(C5:C10, $Z$11) & COUNTIF(C5:C10, $Z$9)+COUNTIF(C5:C10, $Z$12) & COUNTIF(C5:C10, $Z$9)+COUNTIF(C5:C10, $Z$13) & COUNTIF(C5:C10, $Z$9)+COUNTIF(C5:C10, $Z$14) & COUNTIF(C5:C10, $Z$9)+COUNTIF(C5:C10, $Z$15) & COUNTIF(C5:C10, $Z$9)+COUNTIF(C5:C10, $Z$16) & COUNTIF(C5:C10, $Z$9)+COUNTIF(C5:C10, $Z$17) & COUNTIF(C5:C10, $Z$9)+COUNTIF(C5:C10, $Z$18) & COUNTIF(C5:C10, $Z$9)+COUNTIF(C5:C10, $Z$19) & COUNTIF(C5:C10, $Z$9)+COUNTIF(C5:C10, $Z$20) & COUNTIF(C5:C10, $Z$21),""), IF(R$3=7,IF(COUNTA(C4:C10) = R$3,COUNTIF(C4:C10, $Z$9) & COUNTIF(C4:C10, $Z$9)+COUNTIF(C4:C10, $Z$10) & COUNTIF(C4:C10, $Z$9)+COUNTIF(C4:C10, $Z$11) & COUNTIF(C4:C10, $Z$9)+COUNTIF(C4:C10, $Z$12) & COUNTIF(C4:C10, $Z$9)+COUNTIF(C4:C10, $Z$13) & COUNTIF(C4:C10, $Z$9)+COUNTIF(C4:C10, $Z$14) & COUNTIF(C4:C10, $Z$9)+COUNTIF(C4:C10, $Z$15) & COUNTIF(C4:C10, $Z$9)+COUNTIF(C4:C10, $Z$16) & COUNTIF(C4:C10, $Z$9)+COUNTIF(C4:C10, $Z$17) & COUNTIF(C4:C10, $Z$9)+COUNTIF(C4:C10, $Z$18) & COUNTIF(C4:C10, $Z$9)+COUNTIF(C4:C10, $Z$19) & COUNTIF(C4:C10, $Z$9)+COUNTIF(C4:C10, $Z$20) & COUNTIF(C4:C10, $Z$21),""))))))) -> 0010100000000 | AC10: =IF(S$3=2,IF(COUNTA(D9:D10) = S$3,COUNTIF(D9:D10, $Z$9) & COUNTIF(D9:D10, $Z$9)+COUNTIF(D9:D10, $Z$10) & COUNTIF(D9:D10, $Z$9)+COUNTIF(D9:D10, $Z$11) & COUNTIF(D9:D10, $Z$9)+COUNTIF(D9:D10, $Z$12) & COUNTIF(D9:D10, $Z$9)+COUNTIF(D9:D10, $Z$13) & COUNTIF(D9:D10, $Z$9)+COUNTIF(D9:D10, $Z$14) & COUNTIF(D9:D10, $Z$9)+COUNTIF(D9:D10, $Z$15) & COUNTIF(D9:D10, $Z$9)+COUNTIF(D9:D10, $Z$16) & COUNTIF(D9:D10, $Z$9)+COUNTIF(D9:D10, $Z$17) & COUNTIF(D9:D10, $Z$9)+COUNTIF(D9:D10, $Z$18) & COUNTIF(D9:D10, $Z$9)+COUNTIF(D9:D10, $Z$19) & COUNTIF(D9:D10, $Z$9)+COUNTIF(D9:D10, $Z$20) & COUNTIF(D9:D10, $Z$21),""), IF(S$3=3,IF(COUNTA(D8:D10) = S$3,COUNTIF(D8:D10, $Z$9) & COUNTIF(D8:D10, $Z$9)+COUNTIF(D8:D10, $Z$10) & COUNTIF(D8:D10, $Z$9)+COUNTIF(D8:D10, $Z$11) & COUNTIF(D8:D10, $Z$9)+COUNTIF(D8:D10, $Z$12) & COUNTIF(D8:D10, $Z$9)+COUNTIF(D8:D10, $Z$13) & COUNTIF(D8:D10, $Z$9)+COUNTIF(D8:D10, $Z$14) & COUNTIF(D8:D10, $Z$9)+COUNTIF(D8:D10, $Z$15) & COUNTIF(D8:D10, $Z$9)+COUNTIF(D8:D10, $Z$16) & COUNTIF(D8:D10, $Z$9)+COUNTIF(D8:D10, $Z$17) & COUNTIF(D8:D10, $Z$9)+COUNTIF(D8:D10, $Z$18) & COUNTIF(D8:D10, $Z$9)+COUNTIF(D8:D10, $Z$19) & COUNTIF(D8:D10, $Z$9)+COUNTIF(D8:D10, $Z$20) & COUNTIF(D8:D10, $Z$21),""), IF(S$3=4,IF(COUNTA(D7:D10) = S$3,COUNTIF(D7:D10, $Z$9) & COUNTIF(D7:D10, $Z$9)+COUNTIF(D7:D10, $Z$10) & COUNTIF(D7:D10, $Z$9)+COUNTIF(D7:D10, $Z$11) & COUNTIF(D7:D10, $Z$9)+COUNTIF(D7:D10, $Z$12) & COUNTIF(D7:D10, $Z$9)+COUNTIF(D7:D10, $Z$13) & COUNTIF(D7:D10, $Z$9)+COUNTIF(D7:D10, $Z$14) & COUNTIF(D7:D10, $Z$9)+COUNTIF(D7:D10, $Z$15) & COUNTIF(D7:D10, $Z$9)+COUNTIF(D7:D10, $Z$16) & COUNTIF(D7:D10, $Z$9)+COUNTIF(D7:D10, $Z$17) & COUNTIF(D7:D10, $Z$9)+COUNTIF(D7:D10, $Z$18) & COUNTIF(D7:D10, $Z$9)+COUNTIF(D7:D10, $Z$19) & COUNTIF(D7:D10, $Z$9)+COUNTIF(D7:D10, $Z$20) & COUNTIF(D7:D10, $Z$21),""), IF(S$3=5,IF(COUNTA(D6:D10) = S$3,COUNTIF(D6:D10, $Z$9) & COUNTIF(D6:D10, $Z$9)+COUNTIF(D6:D10, $Z$10) & COUNTIF(D6:D10, $Z$9)+COUNTIF(D6:D10, $Z$11) & COUNTIF(D6:D10, $Z$9)+COUNTIF(D6:D10, $Z$12) & COUNTIF(D6:D10, $Z$9)+COUNTIF(D6:D10, $Z$13) & COUNTIF(D6:D10, $Z$9)+COUNTIF(D6:D10, $Z$14) & COUNTIF(D6:D10, $Z$9)+COUNTIF(D6:D10, $Z$15) & COUNTIF(D6:D10, $Z$9)+COUNTIF(D6:D10, $Z$16) & COUNTIF(D6:D10, $Z$9)+COUNTIF(D6:D10, $Z$17) & COUNTIF(D6:D10, $Z$9)+COUNTIF(D6:D10, $Z$18) & COUNTIF(D6:D10, $Z$9)+COUNTIF(D6:D10, $Z$19) & COUNTIF(D6:D10, $Z$9)+COUNTIF(D6:D10, $Z$20) & COUNTIF(D6:D10, $Z$21),""), IF(S$3=6,IF(COUNTA(D5:D10) = S$3,COUNTIF(D5:D10, $Z$9) & COUNTIF(D5:D10, $Z$9)+COUNTIF(D5:D10, $Z$10) & COUNTIF(D5:D10, $Z$9)+COUNTIF(D5:D10, $Z$11) & COUNTIF(D5:D10, $Z$9)+COUNTIF(D5:D10, $Z$12) & COUNTIF(D5:D10, $Z$9)+COUNTIF(D5:D10, $Z$13) & COUNTIF(D5:D10, $Z$9)+COUNTIF(D5:D10, $Z$14) & COUNTIF(D5:D10, $Z$9)+COUNTIF(D5:D10, $Z$15) & COUNTIF(D5:D10, $Z$9)+COUNTIF(D5:D10, $Z$16) & COUNTIF(D5:D10, $Z$9)+COUNTIF(D5:D10, $Z$17) & COUNTIF(D5:D10, $Z$9)+COUNTIF(D5:D10, $Z$18) & COUNTIF(D5:D10, $Z$9)+COUNTIF(D5:D10, $Z$19) & COUNTIF(D5:D10, $Z$9)+COUNTIF(D5:D10, $Z$20) & COUNTIF(D5:D10, $Z$21),""), IF(S$3=7,IF(COUNTA(D4:D10) = S$3,COUNTIF(D4:D10, $Z$9) & COUNTIF(D4:D10, $Z$9)+COUNTIF(D4:D10, $Z$10) & COUNTIF(D4:D10, $Z$9)+COUNTIF(D4:D10, $Z$11) & COUNTIF(D4:D10, $Z$9)+COUNTIF(D4:D10, $Z$12) & COUNTIF(D4:D10, $Z$9)+COUNTIF(D4:D10, $Z$13) & COUNTIF(D4:D10, $Z$9)+COUNTIF(D4:D10, $Z$14) & COUNTIF(D4:D10, $Z$9)+COUNTIF(D4:D10, $Z$15) & COUNTIF(D4:D10, $Z$9)+COUNTIF(D4:D10, $Z$16) & COUNTIF(D4:D10, $Z$9)+COUNTIF(D4:D10, $Z$17) & COUNTIF(D4:D10, $Z$9)+COUNTIF(D4:D10, $Z$18) & COUNTIF(D4:D10, $Z$9)+COUNTIF(D4:D10, $Z$19) & COUNTIF(D4:D10, $Z$9)+COUNTIF(D4:D10, $Z$20) & COUNTIF(D4:D10, $Z$21),""))))))) -> 0000001000010 | AD10: =IF(T$3=2,IF(COUNTA(E9:E10) = T$3,COUNTIF(E9:E10, $Z$9) & COUNTIF(E9:E10, $Z$9)+COUNTIF(E9:E10, $Z$10) & COUNTIF(E9:E10, $Z$9)+COUNTIF(E9:E10, $Z$11) & COUNTIF(E9:E10, $Z$9)+COUNTIF(E9:E10, $Z$12) & COUNTIF(E9:E10, $Z$9)+COUNTIF(E9:E10, $Z$13) & COUNTIF(E9:E10, $Z$9)+COUNTIF(E9:E10, $Z$14) & COUNTIF(E9:E10, $Z$9)+COUNTIF(E9:E10, $Z$15) & COUNTIF(E9:E10, $Z$9)+COUNTIF(E9:E10, $Z$16) & COUNTIF(E9:E10, $Z$9)+COUNTIF(E9:E10, $Z$17) & COUNTIF(E9:E10, $Z$9)+COUNTIF(E9:E10, $Z$18) & COUNTIF(E9:E10, $Z$9)+COUNTIF(E9:E10, $Z$19) & COUNTIF(E9:E10, $Z$9)+COUNTIF(E9:E10, $Z$20) & COUNTIF(E9:E10, $Z$21),""), IF(T$3=3,IF(COUNTA(E8:E10) = T$3,COUNTIF(E8:E10, $Z$9) & COUNTIF(E8:E10, $Z$9)+COUNTIF(E8:E10, $Z$10) & COUNTIF(E8:E10, $Z$9)+COUNTIF(E8:E10, $Z$11) & COUNTIF(E8:E10, $Z$9)+COUNTIF(E8:E10, $Z$12) & COUNTIF(E8:E10, $Z$9)+COUNTIF(E8:E10, $Z$13) & COUNTIF(E8:E10, $Z$9)+COUNTIF(E8:E10, $Z$14) & COUNTIF(E8:E10, $Z$9)+COUNTIF(E8:E10, $Z$15) & COUNTIF(E8:E10, $Z$9)+COUNTIF(E8:E10, $Z$16) & COUNTIF(E8:E10, $Z$9)+COUNTIF(E8:E10, $Z$17) & COUNTIF(E8:E10, $Z$9)+COUNTIF(E8:E10, $Z$18) & COUNTIF(E8:E10, $Z$9)+COUNTIF(E8:E10, $Z$19) & COUNTIF(E8:E10, $Z$9)+COUNTIF(E8:E10, $Z$20) & COUNTIF(E8:E10, $Z$21),""), IF(T$3=4,IF(COUNTA(E7:E10) = T$3,COUNTIF(E7:E10, $Z$9) & COUNTIF(E7:E10, $Z$9)+COUNTIF(E7:E10, $Z$10) & COUNTIF(E7:E10, $Z$9)+COUNTIF(E7:E10, $Z$11) & COUNTIF(E7:E10, $Z$9)+COUNTIF(E7:E10, $Z$12) & COUNTIF(E7:E10, $Z$9)+COUNTIF(E7:E10, $Z$13) & COUNTIF(E7:E10, $Z$9)+COUNTIF(E7:E10, $Z$14) & COUNTIF(E7:E10, $Z$9)+COUNTIF(E7:E10, $Z$15) & COUNTIF(E7:E10, $Z$9)+COUNTIF(E7:E10, $Z$16) & COUNTIF(E7:E10, $Z$9)+COUNTIF(E7:E10, $Z$17) & COUNTIF(E7:E10, $Z$9)+COUNTIF(E7:E10, $Z$18) & COUNTIF(E7:E10, $Z$9)+COUNTIF(E7:E10, $Z$19) & COUNTIF(E7:E10, $Z$9)+COUNTIF(E7:E10, $Z$20) & COUNTIF(E7:E10, $Z$21),""), IF(T$3=5,IF(COUNTA(E6:E10) = T$3,COUNTIF(E6:E10, $Z$9) & COUNTIF(E6:E10, $Z$9)+COUNTIF(E6:E10, $Z$10) & COUNTIF(E6:E10, $Z$9)+COUNTIF(E6:E10, $Z$11) & COUNTIF(E6:E10, $Z$9)+COUNTIF(E6:E10, $Z$12) & COUNTIF(E6:E10, $Z$9)+COUNTIF(E6:E10, $Z$13) & COUNTIF(E6:E10, $Z$9)+COUNTIF(E6:E10, $Z$14) & COUNTIF(E6:E10, $Z$9)+COUNTIF(E6:E10, $Z$15) & COUNTIF(E6:E10, $Z$9)+COUNTIF(E6:E10, $Z$16) & COUNTIF(E6:E10, $Z$9)+COUNTIF(E6:E10, $Z$17) & COUNTIF(E6:E10, $Z$9)+COUNTIF(E6:E10, $Z$18) & COUNTIF(E6:E10, $Z$9)+COUNTIF(E6:E10, $Z$19) & COUNTIF(E6:E10, $Z$9)+COUNTIF(E6:E10, $Z$20) & COUNTIF(E6:E10, $Z$21),""), IF(T$3=6,IF(COUNTA(E5:E10) = T$3,COUNTIF(E5:E10, $Z$9) & COUNTIF(E5:E10, $Z$9)+COUNTIF(E5:E10, $Z$10) & COUNTIF(E5:E10, $Z$9)+COUNTIF(E5:E10, $Z$11) & COUNTIF(E5:E10, $Z$9)+COUNTIF(E5:E10, $Z$12) & COUNTIF(E5:E10, $Z$9)+COUNTIF(E5:E10, $Z$13) & COUNTIF(E5:E10, $Z$9)+COUNTIF(E5:E10, $Z$14) & COUNTIF(E5:E10, $Z$9)+COUNTIF(E5:E10, $Z$15) & COUNTIF(E5:E10, $Z$9)+COUNTIF(E5:E10, $Z$16) & COUNTIF(E5:E10, $Z$9)+COUNTIF(E5:E10, $Z$17) & COUNTIF(E5:E10, $Z$9)+COUNTIF(E5:E10, $Z$18) & COUNTIF(E5:E10, $Z$9)+COUNTIF(E5:E10, $Z$19) & COUNTIF(E5:E10, $Z$9)+COUNTIF(E5:E10, $Z$20) & COUNTIF(E5:E10, $Z$21),""), IF(T$3=7,IF(COUNTA(E4:E10) = T$3,COUNTIF(E4:E10, $Z$9) & COUNTIF(E4:E10, $Z$9)+COUNTIF(E4:E10, $Z$10) & COUNTIF(E4:E10, $Z$9)+COUNTIF(E4:E10, $Z$11) & COUNTIF(E4:E10, $Z$9)+COUNTIF(E4:E10, $Z$12) & COUNTIF(E4:E10, $Z$9)+COUNTIF(E4:E10, $Z$13) & COUNTIF(E4:E10, $Z$9)+COUNTIF(E4:E10, $Z$14) & COUNTIF(E4:E10, $Z$9)+COUNTIF(E4:E10, $Z$15) & COUNTIF(E4:E10, $Z$9)+COUNTIF(E4:E10, $Z$16) & COUNTIF(E4:E10, $Z$9)+COUNTIF(E4:E10, $Z$17) & COUNTIF(E4:E10, $Z$9)+COUNTIF(E4:E10, $Z$18) & COUNTIF(E4:E10, $Z$9)+COUNTIF(E4:E10, $Z$19) & COUNTIF(E4:E10, $Z$9)+COUNTIF(E4:E10, $Z$20) & COUNTIF(E4:E10, $Z$21),""))))))) -> 1111111112110 | AE10: =IF(U$3=2,IF(COUNTA(F9:F10) = U$3,COUNTIF(F9:F10, $Z$9) & COUNTIF(F9:F10, $Z$9)+COUNTIF(F9:F10, $Z$10) & COUNTIF(F9:F10, $Z$9)+COUNTIF(F9:F10, $Z$11) & COUNTIF(F9:F10, $Z$9)+COUNTIF(F9:F10, $Z$12) & COUNTIF(F9:F10, $Z$9)+COUNTIF(F9:F10, $Z$13) & COUNTIF(F9:F10, $Z$9)+COUNTIF(F9:F10, $Z$14) & COUNTIF(F9:F10, $Z$9)+COUNTIF(F9:F10, $Z$15) & COUNTIF(F9:F10, $Z$9)+COUNTIF(F9:F10, $Z$16) & COUNTIF(F9:F10, $Z$9)+COUNTIF(F9:F10, $Z$17) & COUNTIF(F9:F10, $Z$9)+COUNTIF(F9:F10, $Z$18) & COUNTIF(F9:F10, $Z$9)+COUNTIF(F9:F10, $Z$19) & COUNTIF(F9:F10, $Z$9)+COUNTIF(F9:F10, $Z$20) & COUNTIF(F9:F10, $Z$21),""), IF(U$3=3,IF(COUNTA(F8:F10) = U$3,COUNTIF(F8:F10, $Z$9) & COUNTIF(F8:F10, $Z$9)+COUNTIF(F8:F10, $Z$10) & COUNTIF(F8:F10, $Z$9)+COUNTIF(F8:F10, $Z$11) & COUNTIF(F8:F10, $Z$9)+COUNTIF(F8:F10, $Z$12) & COUNTIF(F8:F10, $Z$9)+COUNTIF(F8:F10, $Z$13) & COUNTIF(F8:F10, $Z$9)+COUNTIF(F8:F10, $Z$14) & COUNTIF(F8:F10, $Z$9)+COUNTIF(F8:F10, $Z$15) & COUNTIF(F8:F10, $Z$9)+COUNTIF(F8:F10, $Z$16) & COUNTIF(F8:F10, $Z$9)+COUNTIF(F8:F10, $Z$17) & COUNTIF(F8:F10, $Z$9)+COUNTIF(F8:F10, $Z$18) & COUNTIF(F8:F10, $Z$9)+COUNTIF(F8:F10, $Z$19) & COUNTIF(F8:F10, $Z$9)+COUNTIF(F8:F10, $Z$20) & COUNTIF(F8:F10, $Z$21),""), IF(U$3=4,IF(COUNTA(F7:F10) = U$3,COUNTIF(F7:F10, $Z$9) & COUNTIF(F7:F10, $Z$9)+COUNTIF(F7:F10, $Z$10) & COUNTIF(F7:F10, $Z$9)+COUNTIF(F7:F10, $Z$11) & COUNTIF(F7:F10, $Z$9)+COUNTIF(F7:F10, $Z$12) & COUNTIF(F7:F10, $Z$9)+COUNTIF(F7:F10, $Z$13) & COUNTIF(F7:F10, $Z$9)+COUNTIF(F7:F10, $Z$14) & COUNTIF(F7:F10, $Z$9)+COUNTIF(F7:F10, $Z$15) & COUNTIF(F7:F10, $Z$9)+COUNTIF(F7:F10, $Z$16) & COUNTIF(F7:F10, $Z$9)+COUNTIF(F7:F10, $Z$17) & COUNTIF(F7:F10, $Z$9)+COUNTIF(F7:F10, $Z$18) & COUNTIF(F7:F10, $Z$9)+COUNTIF(F7:F10, $Z$19) & COUNTIF(F7:F10, $Z$9)+COUNTIF(F7:F10, $Z$20) & COUNTIF(F7:F10, $Z$21),""), IF(U$3=5,IF(COUNTA(F6:F10) = U$3,COUNTIF(F6:F10, $Z$9) & COUNTIF(F6:F10, $Z$9)+COUNTIF(F6:F10, $Z$10) & COUNTIF(F6:F10, $Z$9)+COUNTIF(F6:F10, $Z$11) & COUNTIF(F6:F10, $Z$9)+COUNTIF(F6:F10, $Z$12) & COUNTIF(F6:F10, $Z$9)+COUNTIF(F6:F10, $Z$13) & COUNTIF(F6:F10, $Z$9)+COUNTIF(F6:F10, $Z$14) & COUNTIF(F6:F10, $Z$9)+COUNTIF(F6:F10, $Z$15) & COUNTIF(F6:F10, $Z$9)+COUNTIF(F6:F10, $Z$16) & COUNTIF(F6:F10, $Z$9)+COUNTIF(F6:F10, $Z$17) & COUNTIF(F6:F10, $Z$9)+COUNTIF(F6:F10, $Z$18) & COUNTIF(F6:F10, $Z$9)+COUNTIF(F6:F10, $Z$19) & COUNTIF(F6:F10, $Z$9)+COUNTIF(F6:F10, $Z$20) & COUNTIF(F6:F10, $Z$21),""), IF(U$3=6,IF(COUNTA(F5:F10) = U$3,COUNTIF(F5:F10, $Z$9) & COUNTIF(F5:F10, $Z$9)+COUNTIF(F5:F10, $Z$10) & COUNTIF(F5:F10, $Z$9)+COUNTIF(F5:F10, $Z$11) & COUNTIF(F5:F10, $Z$9)+COUNTIF(F5:F10, $Z$12) & COUNTIF(F5:F10, $Z$9)+COUNTIF(F5:F10, $Z$13) & COUNTIF(F5:F10, $Z$9)+COUNTIF(F5:F10, $Z$14) & COUNTIF(F5:F10, $Z$9)+COUNTIF(F5:F10, $Z$15) & COUNTIF(F5:F10, $Z$9)+COUNTIF(F5:F10, $Z$16) & COUNTIF(F5:F10, $Z$9)+COUNTIF(F5:F10, $Z$17) & COUNTIF(F5:F10, $Z$9)+COUNTIF(F5:F10, $Z$18) & COUNTIF(F5:F10, $Z$9)+COUNTIF(F5:F10, $Z$19) & COUNTIF(F5:F10, $Z$9)+COUNTIF(F5:F10, $Z$20) & COUNTIF(F5:F10, $Z$21),""), IF(U$3=7,IF(COUNTA(F4:F10) = U$3,COUNTIF(F4:F10, $Z$9) & COUNTIF(F4:F10, $Z$9)+COUNTIF(F4:F10, $Z$10) & COUNTIF(F4:F10, $Z$9)+COUNTIF(F4:F10, $Z$11) & COUNTIF(F4:F10, $Z$9)+COUNTIF(F4:F10, $Z$12) & COUNTIF(F4:F10, $Z$9)+COUNTIF(F4:F10, $Z$13) & COUNTIF(F4:F10, $Z$9)+COUNTIF(F4:F10, $Z$14) & COUNTIF(F4:F10, $Z$9)+COUNTIF(F4:F10, $Z$15) & COUNTIF(F4:F10, $Z$9)+COUNTIF(F4:F10, $Z$16) & COUNTIF(F4:F10, $Z$9)+COUNTIF(F4:F10, $Z$17) & COUNTIF(F4:F10, $Z$9)+COUNTIF(F4:F10, $Z$18) & COUNTIF(F4:F10, $Z$9)+COUNTIF(F4:F10, $Z$19) & COUNTIF(F4:F10, $Z$9)+COUNTIF(F4:F10, $Z$20) & COUNTIF(F4:F10, $Z$21),""))))))) -> 0010000000010 | AF10: =IF(V$3=2,IF(COUNTA(G9:G10) = V$3,COUNTIF(G9:G10, $Z$9) & COUNTIF(G9:G10, $Z$9)+COUNTIF(G9:G10, $Z$10) & COUNTIF(G9:G10, $Z$9)+COUNTIF(G9:G10, $Z$11) & COUNTIF(G9:G10, $Z$9)+COUNTIF(G9:G10, $Z$12) & COUNTIF(G9:G10, $Z$9)+COUNTIF(G9:G10, $Z$13) & COUNTIF(G9:G10, $Z$9)+COUNTIF(G9:G10, $Z$14) & COUNTIF(G9:G10, $Z$9)+COUNTIF(G9:G10, $Z$15) & COUNTIF(G9:G10, $Z$9)+COUNTIF(G9:G10, $Z$16) & COUNTIF(G9:G10, $Z$9)+COUNTIF(G9:G10, $Z$17) & COUNTIF(G9:G10, $Z$9)+COUNTIF(G9:G10, $Z$18) & COUNTIF(G9:G10, $Z$9)+COUNTIF(G9:G10, $Z$19) & COUNTIF(G9:G10, $Z$9)+COUNTIF(G9:G10, $Z$20) & COUNTIF(G9:G10, $Z$21),""), IF(V$3=3,IF(COUNTA(G8:G10) = V$3,COUNTIF(G8:G10, $Z$9) & COUNTIF(G8:G10, $Z$9)+COUNTIF(G8:G10, $Z$10) & COUNTIF(G8:G10, $Z$9)+COUNTIF(G8:G10, $Z$11) & COUNTIF(G8:G10, $Z$9)+COUNTIF(G8:G10, $Z$12) & COUNTIF(G8:G10, $Z$9)+COUNTIF(G8:G10, $Z$13) & COUNTIF(G8:G10, $Z$9)+COUNTIF(G8:G10, $Z$14) & COUNTIF(G8:G10, $Z$9)+COUNTIF(G8:G10, $Z$15) & COUNTIF(G8:G10, $Z$9)+COUNTIF(G8:G10, $Z$16) & COUNTIF(G8:G10, $Z$9)+COUNTIF(G8:G10, $Z$17) & COUNTIF(G8:G10, $Z$9)+COUNTIF(G8:G10, $Z$18) & COUNTIF(G8:G10, $Z$9)+COUNTIF(G8:G10, $Z$19) & COUNTIF(G8:G10, $Z$9)+COUNTIF(G8:G10, $Z$20) & COUNTIF(G8:G10, $Z$21),""), IF(V$3=4,IF(COUNTA(G7:G10) = V$3,COUNTIF(G7:G10, $Z$9) & COUNTIF(G7:G10, $Z$9)+COUNTIF(G7:G10, $Z$10) & COUNTIF(G7:G10, $Z$9)+COUNTIF(G7:G10, $Z$11) & COUNTIF(G7:G10, $Z$9)+COUNTIF(G7:G10, $Z$12) & COUNTIF(G7:G10, $Z$9)+COUNTIF(G7:G10, $Z$13) & COUNTIF(G7:G10, $Z$9)+COUNTIF(G7:G10, $Z$14) & COUNTIF(G7:G10, $Z$9)+COUNTIF(G7:G10, $Z$15) & COUNTIF(G7:G10, $Z$9)+COUNTIF(G7:G10, $Z$16) & COUNTIF(G7:G10, $Z$9)+COUNTIF(G7:G10, $Z$17) & COUNTIF(G7:G10, $Z$9)+COUNTIF(G7:G10, $Z$18) & COUNTIF(G7:G10, $Z$9)+COUNTIF(G7:G10, $Z$19) & COUNTIF(G7:G10, $Z$9)+COUNTIF(G7:G10, $Z$20) & COUNTIF(G7:G10, $Z$21),""), IF(V$3=5,IF(COUNTA(G6:G10) = V$3,COUNTIF(G6:G10, $Z$9) & COUNTIF(G6:G10, $Z$9)+COUNTIF(G6:G10, $Z$10) & COUNTIF(G6:G10, $Z$9)+COUNTIF(G6:G10, $Z$11) & COUNTIF(G6:G10, $Z$9)+COUNTIF(G6:G10, $Z$12) & COUNTIF(G6:G10, $Z$9)+COUNTIF(G6:G10, $Z$13) & COUNTIF(G6:G10, $Z$9)+COUNTIF(G6:G10, $Z$14) & COUNTIF(G6:G10, $Z$9)+COUNTIF(G6:G10, $Z$15) & COUNTIF(G6:G10, $Z$9)+COUNTIF(G6:G10, $Z$16) & COUNTIF(G6:G10, $Z$9)+COUNTIF(G6:G10, $Z$17) & COUNTIF(G6:G10, $Z$9)+COUNTIF(G6:G10, $Z$18) & COUNTIF(G6:G10, $Z$9)+COUNTIF(G6:G10, $Z$19) & COUNTIF(G6:G10, $Z$9)+COUNTIF(G6:G10, $Z$20) & COUNTIF(G6:G10, $Z$21),""), IF(V$3=6,IF(COUNTA(G5:G10) = V$3,COUNTIF(G5:G10, $Z$9) & COUNTIF(G5:G10, $Z$9)+COUNTIF(G5:G10, $Z$10) & COUNTIF(G5:G10, $Z$9)+COUNTIF(G5:G10, $Z$11) & COUNTIF(G5:G10, $Z$9)+COUNTIF(G5:G10, $Z$12) & COUNTIF(G5:G10, $Z$9)+COUNTIF(G5:G10, $Z$13) & COUNTIF(G5:G10, $Z$9)+COUNTIF(G5:G10, $Z$14) & COUNTIF(G5:G10, $Z$9)+COUNTIF(G5:G10, $Z$15) & COUNTIF(G5:G10, $Z$9)+COUNTIF(G5:G10, $Z$16) & COUNTIF(G5:G10, $Z$9)+COUNTIF(G5:G10, $Z$17) & COUNTIF(G5:G10, $Z$9)+COUNTIF(G5:G10, $Z$18) & COUNTIF(G5:G10, $Z$9)+COUNTIF(G5:G10, $Z$19) & COUNTIF(G5:G10, $Z$9)+COUNTIF(G5:G10, $Z$20) & COUNTIF(G5:G10, $Z$21),""), IF(V$3=7,IF(COUNTA(G4:G10) = V$3,COUNTIF(G4:G10, $Z$9) & COUNTIF(G4:G10, $Z$9)+COUNTIF(G4:G10, $Z$10) & COUNTIF(G4:G10, $Z$9)+COUNTIF(G4:G10, $Z$11) & COUNTIF(G4:G10, $Z$9)+COUNTIF(G4:G10, $Z$12) & COUNTIF(G4:G10, $Z$9)+COUNTIF(G4:G10, $Z$13) & COUNTIF(G4:G10, $Z$9)+COUNTIF(G4:G10, $Z$14) & COUNTIF(G4:G10, $Z$9)+COUNTIF(G4:G10, $Z$15) & COUNTIF(G4:G10, $Z$9)+COUNTIF(G4:G10, $Z$16) & COUNTIF(G4:G10, $Z$9)+COUNTIF(G4:G10, $Z$17) & COUNTIF(G4:G10, $Z$9)+COUNTIF(G4:G10, $Z$18) & COUNTIF(G4:G10, $Z$9)+COUNTIF(G4:G10, $Z$19) & COUNTIF(G4:G10, $Z$9)+COUNTIF(G4:G10, $Z$20) & COUNTIF(G4:G10, $Z$21),""))))))) -> 0001000001000 | AG10: =IF(W$3=2,IF(COUNTA(H9:H10) = W$3,COUNTIF(H9:H10, $Z$9) & COUNTIF(H9:H10, $Z$9)+COUNTIF(H9:H10, $Z$10) & COUNTIF(H9:H10, $Z$9)+COUNTIF(H9:H10, $Z$11) & COUNTIF(H9:H10, $Z$9)+COUNTIF(H9:H10, $Z$12) & COUNTIF(H9:H10, $Z$9)+COUNTIF(H9:H10, $Z$13) & COUNTIF(H9:H10, $Z$9)+COUNTIF(H9:H10, $Z$14) & COUNTIF(H9:H10, $Z$9)+COUNTIF(H9:H10, $Z$15) & COUNTIF(H9:H10, $Z$9)+COUNTIF(H9:H10, $Z$16) & COUNTIF(H9:H10, $Z$9)+COUNTIF(H9:H10, $Z$17) & COUNTIF(H9:H10, $Z$9)+COUNTIF(H9:H10, $Z$18) & COUNTIF(H9:H10, $Z$9)+COUNTIF(H9:H10, $Z$19) & COUNTIF(H9:H10, $Z$9)+COUNTIF(H9:H10, $Z$20) & COUNTIF(H9:H10, $Z$21),""), IF(W$3=3,IF(COUNTA(H8:H10) = W$3,COUNTIF(H8:H10, $Z$9) & COUNTIF(H8:H10, $Z$9)+COUNTIF(H8:H10, $Z$10) & COUNTIF(H8:H10, $Z$9)+COUNTIF(H8:H10, $Z$11) & COUNTIF(H8:H10, $Z$9)+COUNTIF(H8:H10, $Z$12) & COUNTIF(H8:H10, $Z$9)+COUNTIF(H8:H10, $Z$13) & COUNTIF(H8:H10, $Z$9)+COUNTIF(H8:H10, $Z$14) & COUNTIF(H8:H10, $Z$9)+COUNTIF(H8:H10, $Z$15) & COUNTIF(H8:H10, $Z$9)+COUNTIF(H8:H10, $Z$16) & COUNTIF(H8:H10, $Z$9)+COUNTIF(H8:H10, $Z$17) & COUNTIF(H8:H10, $Z$9)+COUNTIF(H8:H10, $Z$18) & COUNTIF(H8:H10, $Z$9)+COUNTIF(H8:H10, $Z$19) & COUNTIF(H8:H10, $Z$9)+COUNTIF(H8:H10, $Z$20) & COUNTIF(H8:H10, $Z$21),""), IF(W$3=4,IF(COUNTA(H7:H10) = W$3,COUNTIF(H7:H10, $Z$9) & COUNTIF(H7:H10, $Z$9)+COUNTIF(H7:H10, $Z$10) & COUNTIF(H7:H10, $Z$9)+COUNTIF(H7:H10, $Z$11) & COUNTIF(H7:H10, $Z$9)+COUNTIF(H7:H10, $Z$12) & COUNTIF(H7:H10, $Z$9)+COUNTIF(H7:H10, $Z$13) & COUNTIF(H7:H10, $Z$9)+COUNTIF(H7:H10, $Z$14) & COUNTIF(H7:H10, $Z$9)+COUNTIF(H7:H10, $Z$15) & COUNTIF(H7:H10, $Z$9)+COUNTIF(H7:H10, $Z$16) & COUNTIF(H7:H10, $Z$9)+COUNTIF(H7:H10, $Z$17) & COUNTIF(H7:H10, $Z$9)+COUNTIF(H7:H10, $Z$18) & COUNTIF(H7:H10, $Z$9)+COUNTIF(H7:H10, $Z$19) & COUNTIF(H7:H10, $Z$9)+COUNTIF(H7:H10, $Z$20) & COUNTIF(H7:H10, $Z$21),""), IF(W$3=5,IF(COUNTA(H6:H10) = W$3,COUNTIF(H6:H10, $Z$9) & COUNTIF(H6:H10, $Z$9)+COUNTIF(H6:H10, $Z$10) & COUNTIF(H6:H10, $Z$9)+COUNTIF(H6:H10, $Z$11) & COUNTIF(H6:H10, $Z$9)+COUNTIF(H6:H10, $Z$12) & COUNTIF(H6:H10, $Z$9)+COUNTIF(H6:H10, $Z$13) & COUNTIF(H6:H10, $Z$9)+COUNTIF(H6:H10, $Z$14) & COUNTIF(H6:H10, $Z$9)+COUNTIF(H6:H10, $Z$15) & COUNTIF(H6:H10, $Z$9)+COUNTIF(H6:H10, $Z$16) & COUNTIF(H6:H10, $Z$9)+COUNTIF(H6:H10, $Z$17) & COUNTIF(H6:H10, $Z$9)+COUNTIF(H6:H10, $Z$18) & COUNTIF(H6:H10, $Z$9)+COUNTIF(H6:H10, $Z$19) & COUNTIF(H6:H10, $Z$9)+COUNTIF(H6:H10, $Z$20) & COUNTIF(H6:H10, $Z$21),""), IF(W$3=6,IF(COUNTA(H5:H10) = W$3,COUNTIF(H5:H10, $Z$9) & COUNTIF(H5:H10, $Z$9)+COUNTIF(H5:H10, $Z$10) & COUNTIF(H5:H10, $Z$9)+COUNTIF(H5:H10, $Z$11) & COUNTIF(H5:H10, $Z$9)+COUNTIF(H5:H10, $Z$12) & COUNTIF(H5:H10, $Z$9)+COUNTIF(H5:H10, $Z$13) & COUNTIF(H5:H10, $Z$9)+COUNTIF(H5:H10, $Z$14) & COUNTIF(H5:H10, $Z$9)+COUNTIF(H5:H10, $Z$15) & COUNTIF(H5:H10, $Z$9)+COUNTIF(H5:H10, $Z$16) & COUNTIF(H5:H10, $Z$9)+COUNTIF(H5:H10, $Z$17) & COUNTIF(H5:H10, $Z$9)+COUNTIF(H5:H10, $Z$18) & COUNTIF(H5:H10, $Z$9)+COUNTIF(H5:H10, $Z$19) & COUNTIF(H5:H10, $Z$9)+COUNTIF(H5:H10, $Z$20) & COUNTIF(H5:H10, $Z$21),""), IF(W$3=7,IF(COUNTA(H4:H10) = W$3,COUNTIF(H4:H10, $Z$9) & COUNTIF(H4:H10, $Z$9)+COUNTIF(H4:H10, $Z$10) & COUNTIF(H4:H10, $Z$9)+COUNTIF(H4:H10, $Z$11) & COUNTIF(H4:H10, $Z$9)+COUNTIF(H4:H10, $Z$12) & COUNTIF(H4:H10, $Z$9)+COUNTIF(H4:H10, $Z$13) & COUNTIF(H4:H10, $Z$9)+COUNTIF(H4:H10, $Z$14) & COUNTIF(H4:H10, $Z$9)+COUNTIF(H4:H10, $Z$15) & COUNTIF(H4:H10, $Z$9)+COUNTIF(H4:H10, $Z$16) & COUNTIF(H4:H10, $Z$9)+COUNTIF(H4:H10, $Z$17) & COUNTIF(H4:H10, $Z$9)+COUNTIF(H4:H10, $Z$18) & COUNTIF(H4:H10, $Z$9)+COUNTIF(H4:H10, $Z$19) & COUNTIF(H4:H10, $Z$9)+COUNTIF(H4:H10, $Z$20) & COUNTIF(H4:H10, $Z$21),""))))))) -> 0000000010100 | AI10: 7 | AJ10: =$Z$10&"-7" -> AA-7 | AK10: {=SUMPRODUCT(--(MID(AB$10:AB$135, SUMIF($Z$9:$Z$21, LEFT($AJ10,2), $Y$9:$Y$21), 1) = RIGHT($AJ10, 1)), J$10:J$135)} -> 0 | AL10: {=SUMPRODUCT(--(MID(AC$10:AC$135, SUMIF($Z$9:$Z$21, LEFT($AJ10,2), $Y$9:$Y$21), 1) = RIGHT($AJ10, 1)), K$10:K$135)} -> 0 | AM10: {=SUMPRODUCT(--(MID(AD$10:AD$135, SUMIF($Z$9:$Z$21, LEFT($AJ10,2), $Y$9:$Y$21), 1) = RIGHT($AJ10, 1)), L$10:L$135)} -> 0 | AN10: {=SUMPRODUCT(--(MID(AE$10:AE$135, SUMIF($Z$9:$Z$21, LEFT($AJ10,2), $Y$9:$Y$21), 1) = RIGHT($AJ10, 1)), M$10:M$135)} -> 0 | AO10: {=SUMPRODUCT(--(MID(AF$10:AF$135, SUMIF($Z$9:$Z$21, LEFT($AJ10,2), $Y$9:$Y$21), 1) = RIGHT($AJ10, 1)), N$10:N$135)} -> 0 | AP10: {=SUMPRODUCT(--(MID(AG$10:AG$135, SUMIF($Z$9:$Z$21, LEFT($AJ10,2), $Y$9:$Y$21), 1) = RIGHT($AJ10, 1)), O$10:O$135)} -> 0 | AR10: =Z9 -> WC | AS10: {=SUMPRODUCT($AI$10:$AI$113,AK$10:AK$113,IF(LEFT($AJ$10:$AJ$113,2)=$AR10,1,0))} -> 0 | AT10: {=SUMPRODUCT($AI$10:$AI$113,AL$10:AL$113,IF(LEFT($AJ$10:$AJ$113,2)=$AR10,1,0))} -> 4 | AU10: {=SUMPRODUCT($AI$10:$AI$113,AM$10:AM$113,IF(LEFT($AJ$10:$AJ$113,2)=$AR10,1,0))} -> 8 | AV10: {=SUMPRODUCT($AI$10:$AI$113,AN$10:AN$113,IF(LEFT($AJ$10:$AJ$113,2)=$AR10,1,0))} -> 2 | AW10: {=SUMPRODUCT($AI$10:$AI$113,AO$10:AO$113,IF(LEFT($AJ$10:$AJ$113,2)=$AR10,1,0))} -> 2 | AX10: {=SUMPRODUCT($AI$10:$AI$113,AP$10:AP$113,IF(LEFT($AJ$10:$AJ$113,2)=$AR10,1,0))} -> 0
