Workbook

Sheet Test Case Summary
A1: Pig Style (Megaways) - QA Test Suite
A3: Client | B3: FEG (Fortuna Entertainment Group)
A4: Game | B4: Pig Style - 6-reel Megaways, up to 117,649 ways
A5: Source: Game Rules | B5: Pig_Style_GR_Eng_2.docx
A6: Source: Math File | B6: pig_style_R7_1.xlsx (R7.1)
A7: Prepared by | B7: Pixentech QA
A8: Prepared on | B8: 23 Oct 2026
A9: Test case ID format | B9: PS-<AREA>-NNN
A10: Bet convention | B10: Math pays are credits at total bet 20. Win = Bet x Pay / 20 x Ways x product of wild multipliers
A12: Sheet | B12: Total TCs | C12: P0 | D12: P1 | E12: P2 | F12: P3 | G12: Automation: Yes | H12: Automation: Partial | I12: Requires Spec/Confirmation
A13: Functional Testing | B13: =COUNTA('Functional Testing'!A:A)-1 -> 90 | C13: =COUNTIF('Functional Testing'!K:K,"P0") -> 49 | D13: =COUNTIF('Functional Testing'!K:K,"P1") -> 28 | E13: =COUNTIF('Functional Testing'!K:K,"P2") -> 11 | F13: =COUNTIF('Functional Testing'!K:K,"P3") -> 2 | G13: =COUNTIF('Functional Testing'!N:N,"Yes") -> 66 | H13: =COUNTIF('Functional Testing'!N:N,"Partial") -> 17 | I13: =COUNTIF('Functional Testing'!I:I,"Requires Specification*") -> 10
A14: Math Validation | B14: =COUNTA('Math Validation'!A:A)-1 -> 63 | C14: =COUNTIF('Math Validation'!K:K,"P0") -> 45 | D14: =COUNTIF('Math Validation'!K:K,"P1") -> 10 | E14: =COUNTIF('Math Validation'!K:K,"P2") -> 8 | F14: =COUNTIF('Math Validation'!K:K,"P3") -> 0 | G14: =COUNTIF('Math Validation'!N:N,"Yes") -> 57 | H14: =COUNTIF('Math Validation'!N:N,"Partial") -> 0 | I14: =COUNTIF('Math Validation'!I:I,"Requires Specification*") -> 12
A15: Feature Testing | B15: =COUNTA('Feature Testing'!A:A)-1 -> 59 | C15: =COUNTIF('Feature Testing'!K:K,"P0") -> 40 | D15: =COUNTIF('Feature Testing'!K:K,"P1") -> 18 | E15: =COUNTIF('Feature Testing'!K:K,"P2") -> 1 | F15: =COUNTIF('Feature Testing'!K:K,"P3") -> 0 | G15: =COUNTIF('Feature Testing'!N:N,"Yes") -> 50 | H15: =COUNTIF('Feature Testing'!N:N,"Partial") -> 6 | I15: =COUNTIF('Feature Testing'!I:I,"Requires Specification*") -> 10
A16: Edge & Boundary Cases | B16: =COUNTA('Edge & Boundary Cases'!A:A)-1 -> 42 | C16: =COUNTIF('Edge & Boundary Cases'!K:K,"P0") -> 16 | D16: =COUNTIF('Edge & Boundary Cases'!K:K,"P1") -> 17 | E16: =COUNTIF('Edge & Boundary Cases'!K:K,"P2") -> 7 | F16: =COUNTIF('Edge & Boundary Cases'!K:K,"P3") -> 2 | G16: =COUNTIF('Edge & Boundary Cases'!N:N,"Yes") -> 40 | H16: =COUNTIF('Edge & Boundary Cases'!N:N,"Partial") -> 0 | I16: =COUNTIF('Edge & Boundary Cases'!I:I,"Requires Specification*") -> 4
A17: Regression Suite | B17: =COUNTA('Regression Suite'!A:A)-1 -> 162 | C17: =COUNTIF('Regression Suite'!K:K,"P0") -> 15 | D17: =COUNTIF('Regression Suite'!K:K,"P1") -> 119 | E17: =COUNTIF('Regression Suite'!K:K,"P2") -> 28 | F17: =COUNTIF('Regression Suite'!K:K,"P3") -> 0 | G17: =COUNTIF('Regression Suite'!N:N,"Yes") -> 152 | H17: =COUNTIF('Regression Suite'!N:N,"Partial") -> 5 | I17: =COUNTIF('Regression Suite'!I:I,"Requires Specification*") -> 18
A18: UI-UX Testing | B18: =COUNTA('UI-UX Testing'!A:A)-1 -> 47 | C18: =COUNTIF('UI-UX Testing'!K:K,"P0") -> 1 | D18: =COUNTIF('UI-UX Testing'!K:K,"P1") -> 19 | E18: =COUNTIF('UI-UX Testing'!K:K,"P2") -> 18 | F18: =COUNTIF('UI-UX Testing'!K:K,"P3") -> 9 | G18: =COUNTIF('UI-UX Testing'!N:N,"Yes") -> 1 | H18: =COUNTIF('UI-UX Testing'!N:N,"Partial") -> 41 | I18: =COUNTIF('UI-UX Testing'!I:I,"Requires Specification*") -> 1
A19: Compatibility Testing | B19: =COUNTA('Compatibility Testing'!A:A)-1 -> 21 | C19: =COUNTIF('Compatibility Testing'!K:K,"P0") -> 3 | D19: =COUNTIF('Compatibility Testing'!K:K,"P1") -> 9 | E19: =COUNTIF('Compatibility Testing'!K:K,"P2") -> 7 | F19: =COUNTIF('Compatibility Testing'!K:K,"P3") -> 2 | G19: =COUNTIF('Compatibility Testing'!N:N,"Yes") -> 0 | H19: =COUNTIF('Compatibility Testing'!N:N,"Partial") -> 13 | I19: =COUNTIF('Compatibility Testing'!I:I,"Requires Specification*") -> 0
A20: Interruption & Recovery | B20: =COUNTA('Interruption & Recovery'!A:A)-1 -> 30 | C20: =COUNTIF('Interruption & Recovery'!K:K,"P0") -> 24 | D20: =COUNTIF('Interruption & Recovery'!K:K,"P1") -> 6 | E20: =COUNTIF('Interruption & Recovery'!K:K,"P2") -> 0 | F20: =COUNTIF('Interruption & Recovery'!K:K,"P3") -> 0 | G20: =COUNTIF('Interruption & Recovery'!N:N,"Yes") -> 30 | H20: =COUNTIF('Interruption & Recovery'!N:N,"Partial") -> 0 | I20: =COUNTIF('Interruption & Recovery'!I:I,"Requires Specification*") -> 2
A21: STR - Transaction Testing | B21: =COUNTA('STR - Transaction Testing'!A:A)-1 -> 27 | C21: =COUNTIF('STR - Transaction Testing'!K:K,"P0") -> 23 | D21: =COUNTIF('STR - Transaction Testing'!K:K,"P1") -> 4 | E21: =COUNTIF('STR - Transaction Testing'!K:K,"P2") -> 0 | F21: =COUNTIF('STR - Transaction Testing'!K:K,"P3") -> 0 | G21: =COUNTIF('STR - Transaction Testing'!N:N,"Yes") -> 22 | H21: =COUNTIF('STR - Transaction Testing'!N:N,"Partial") -> 4 | I21: =COUNTIF('STR - Transaction Testing'!I:I,"Requires Specification*") -> 1
A22: Error Handling | B22: =COUNTA('Error Handling'!A:A)-1 -> 20 | C22: =COUNTIF('Error Handling'!K:K,"P0") -> 8 | D22: =COUNTIF('Error Handling'!K:K,"P1") -> 11 | E22: =COUNTIF('Error Handling'!K:K,"P2") -> 1 | F22: =COUNTIF('Error Handling'!K:K,"P3") -> 0 | G22: =COUNTIF('Error Handling'!N:N,"Yes") -> 20 | H22: =COUNTIF('Error Handling'!N:N,"Partial") -> 0 | I22: =COUNTIF('Error Handling'!I:I,"Requires Specification*") -> 0
A23: Total (incl. Regression) | B23: =SUM(B13:B22) -> 561 | C23: =SUM(C13:C22) -> 224 | D23: =SUM(D13:D22) -> 241 | E23: =SUM(E13:E22) -> 81 | F23: =SUM(F13:F22) -> 15 | G23: =SUM(G13:G22) -> 438 | H23: =SUM(H13:H22) -> 86 | I23: =SUM(I13:I22) -> 58
A24: Total unique (excl. Regression) | B24: =B23-B17 -> 399 | C24: =C23-C17 -> 209 | D24: =D23-D17 -> 122 | E24: =E23-E17 -> 53 | F24: =F23-F17 -> 15 | G24: =G23-G17 -> 286 | H24: =H23-H17 -> 81 | I24: =I23-I17 -> 40
A26: Legend
A27: P0 | B27: Release blocker: money, math, compliance, state integrity
A28: P1 | B28: Major functionality; must pass before client release
A29: P2 | B29: Important but has workaround / cosmetic with impact
A30: P3 | B30: Minor / cosmetic
A31: Yellow cells | B31: Columns to fill during execution: Actual Result, Status, Defect ID
A32: Orange Expected Result | B32: Case depends on a spec item marked 'Requires Specification/Confirmation' (see Defect-Observation Log)
A33: Status values | B33: Not Run, Pass, Fail, Blocked, N/A, Spec Confirmation
A34: Regression Suite priority | B34: Execution order: P0 = Smoke (every build), P1 = Core (money, math, features, state), P2 = Extended. Source priority kept in Remarks
A35: Math Reference sheet | B35: Paytable and weights extracted from the math file, with x-bet values as formulas
A37: Example of a completed row (for format reference only)
A38: Test Case ID | B38: PS-FUN-021
A39: Actual Result | B39: Win field 0.75; balance 99.75 from 100.00 at bet 1.00
A40: Status | B40: Pass
A41: Defect ID | B41: (blank when passed, e.g. PS-DEF-012 when failed)

Sheet Functional Testing
A1: Test Case ID | B1: Module | C1: Feature | D1: Sub-Feature | E1: Test Scenario | F1: Preconditions | G1: Test Data | H1: Detailed Test Steps | I1: Expected Result | J1: Actual Result | K1: Priority | L1: Severity | M1: Test Type | N1: Automation Candidate | O1: Environment | P1: Browser/Device | Q1: Status | R1: Defect ID | S1: Remarks
A2: PS-FUN-001 | B2: Functional | C2: Game Launch | D2: Initial load | E2: Verify the game launches from the operator lobby in real-money mode and lands on the base game with correct initial state | F2: Valid player session with funded wallet; game enabled for operator | G2: Balance: 500.00 EUR; default bet as configured | H2: 1. Log in to the operator lobby 2. Launch Pig Style 3. Wait for the loader to complete 4. Observe reels, bet field, balance field and win field | I2: Loader completes without error; 6 reels displayed; balance equals wallet balance (500.00); bet field shows configured default bet; win field shows 0.00 or blank; Play button enabled | K2: P0 | L2: Critical | M2: Functional | N2: Yes | O2: QA / Staging (Game Client + RGS) | P2: Desktop + Mobile (all supported) | Q2: Not Run | S2: Ref: GR-01, GR-19, GR-21
A3: PS-FUN-002 | B3: Functional | C3: Game Launch | D3: Splash screen | E3: Verify the splash/intro screen displays on first launch and can be dismissed to reach the base game | F3: First launch for the player (no prior splash preference) | G3: N/A | H3: 1. Launch the game 2. Observe splash screen 3. Press Continue/Play on the splash 4. Reopen game after enabling 'do not show' option in Splash Screen Settings (if present) | I3: Splash shown on first launch and dismisses to base game; when disabled via Splash Screen Settings the game opens directly to base game on next launch | K3: P2 | L3: Medium | M3: Functional | N3: Yes | O3: QA / Staging (Game Client + RGS) | P3: Desktop + Mobile (all supported) | Q3: Not Run | S3: Ref: GR-46
A4: PS-FUN-003 | B4: Functional | C4: Game Launch | D4: Currency | E4: Verify all monetary fields render in the session currency | F4: Sessions available in EUR, RON and one non-decimal currency if supported | G4: Currencies: EUR, RON | H4: 1. Launch the game with EUR session 2. Check bet, balance, win, paytable and Buy cost values 3. Repeat with RON session | I4: All monetary values show the session currency symbol/code with correct decimal precision; no mixing of currencies; paytable values recalculated in session currency | K4: P1 | L4: High | M4: Functional | N4: Partial | O4: QA / Staging (Game Client + RGS) | P4: Desktop + Mobile (all supported) | Q4: Not Run | S4: Ref: GR-19
A5: PS-FUN-004 | B5: Functional | C5: Game Launch | D5: Demo / Fun mode | E5: Verify the game launches in fun mode with virtual balance and no wallet transactions | F5: Fun mode URL available from operator | G5: Fun balance as configured by RGS | H5: 1. Launch game in fun mode 2. Place 5 spins 3. Check RGS/wallet logs | I5: Game playable with virtual balance; no debit/credit calls to the real-money wallet; fun mode indicator shown if required by operator | K5: P2 | L5: Medium | M5: Functional | N5: Partial | O5: QA / Staging (Game Client + RGS) | P5: Desktop + Mobile (all supported) | Q5: Not Run | S5: Ref: GR-19
A6: PS-FUN-005 | B6: Functional | C6: Base Game | D6: Reel layout | E6: Verify the base game shows 6 reels and each reel displays between 2 and 7 symbols per spin | F6: Base game loaded | G6: Observe 50 spins | H6: 1. Spin 50 times at any bet 2. For each spin, count visible symbol rows on every reel 3. Record min and max per reel | I6: Every reel shows a symbol count in the range 2..7 on every spin; no reel shows 1 or 8+ positions; reel heights vary independently per reel | K6: P0 | L6: Critical | M6: Functional | N6: Yes | O6: QA / Staging (Game Client + RGS) | P6: Desktop + Mobile (all supported) | Q6: Not Run | S6: Ref: GR-01, GR-02, M-06
A7: PS-FUN-006 | B7: Functional | C7: Base Game | D7: Ways counter | E7: Verify the ways-to-win counter equals the product of the symbol counts on all 6 reels | F7: Base game loaded; ways counter visible | G7: Example rows [2,3,4,5,6,7] => 2x3x4x5x6x7 = 5,040 ways | H7: 1. Spin until a result is observed 2. Count rows on each reel 3. Multiply counts 4. Compare to on-screen ways counter | I7: Ways counter equals product of reel heights for every spin (e.g. 5,040 for [2,3,4,5,6,7]); counter updates when the reels stop | K7: P0 | L7: Critical | M7: Functional | N7: Yes | O7: QA / Staging (Game Client + RGS) | P7: Desktop + Mobile (all supported) | Q7: Not Run | S7: Ref: GR-01, GR-02, M-06
A8: PS-FUN-007 | B8: Functional | C8: Base Game | D8: Ways counter | E8: Verify the maximum ways value 117,649 is displayed when all reels show 7 symbols | F8: Test tool / forced outcome to set all reel heights to 7 | G8: Rows [7,7,7,7,7,7] => 7^6 = 117,649 | H8: 1. Force reel heights 7 on all reels 2. Spin 3. Read ways counter | I8: Ways counter shows 117,649 formatted with thousands separator; no truncation | K8: P1 | L8: High | M8: Functional | N8: Yes | O8: QA / Staging (Game Client + RGS) | P8: Desktop Chrome (latest) | Q8: Not Run | S8: Ref: GR-01, M-06
A9: PS-FUN-008 | B9: Functional | C9: Base Game | D9: Ways counter | E9: Verify the minimum ways value 64 is displayed when all reels show 2 symbols | F9: Test tool / forced outcome | G9: Rows [2,2,2,2,2,2] => 2^6 = 64 | H9: 1. Force reel heights 2 on all reels 2. Spin 3. Read ways counter | I9: Ways counter shows 64 | K9: P2 | L9: Medium | M9: Functional | N9: Yes | O9: QA / Staging (Game Client + RGS) | P9: Desktop Chrome (latest) | Q9: Not Run | S9: Ref: GR-01, M-06
A10: PS-FUN-009 | B10: Functional | C10: Spin | D10: Start spin | E10: Verify pressing the Play button starts exactly one game round at the selected bet | F10: Balance >= selected bet | G10: Bet: 1.00; Balance: 100.00 | H10: 1. Note balance 2. Press Play once 3. Wait for round to complete | I10: One round starts; balance reduces by exactly 1.00 at spin start; one bet transaction in RGS; reels spin and stop; any win added after evaluation | K10: P0 | L10: Critical | M10: Functional | N10: Yes | O10: QA / Staging (Game Client + RGS) | P10: Desktop + Mobile (all supported) | Q10: Not Run | S10: Ref: GR-22
A11: PS-FUN-010 | B11: Functional | C11: Spin | D11: Space bar | E11: Verify pressing the space bar starts a game round on desktop | F11: Desktop browser; game canvas focused; no popup open | G11: Bet: 1.00 | H11: 1. Click on the game area to focus 2. Press space bar once 3. Observe round | I11: One round starts exactly as with the Play button; balance debited once | K11: P1 | L11: Medium | M11: Functional | N11: Yes | O11: QA / Staging (Game Client + RGS) | P11: Desktop Chrome (latest) | Q11: Not Run | S11: Ref: GR-44
A12: PS-FUN-011 | B12: Functional | C12: Spin | D12: Space bar | E12: Verify the space bar does not start a spin while a menu, bet panel, paytable or Buy Feature interface is open | F12: Desktop | G12: Bet: 1.00 | H12: 1. Open bet panel and press space 2. Open Menu and press space 3. Open Game Info and press space 4. Open Buy Feature interface and press space | I12: No spin starts and no balance change in any case; open panel remains stable | K12: P1 | L12: High | M12: Negative | N12: Yes | O12: QA / Staging (Game Client + RGS) | P12: Desktop Chrome (latest) | Q12: Not Run | S12: Ref: GR-44
A13: PS-FUN-012 | B13: Functional | C13: Spin | D13: Quick Stop | E13: Verify pressing the spin button again during reel spin stops the reels early without changing the outcome | F13: Quick Stop available in jurisdiction | G13: Bet: 1.00; compare result with RGS response | H13: 1. Press Play 2. Immediately press the spin button again 3. Compare final reel result and win with RGS round response | I13: Reels stop early; displayed symbols and win identical to RGS outcome; no second round started; no extra debit | K13: P1 | L13: High | M13: Functional | N13: Yes | O13: QA / Staging (Game Client + RGS) | P13: Desktop + Mobile (all supported) | Q13: Not Run | S13: Ref: GR-31
... A91: PS-FUN-090 | B91: Functional | C91: Compliance | D91: Pay table ID | E91: Verify the Pay table ID shown in rules matches the deployed math/config identifier | F91: Game Info open; deployed config ID known | G91: Rules: 'Pig Style'; math file game name: 'DogHouseMegaways9700' | H91: 1. Read Pay table ID 2. Compare with RGS math configuration ID | I91: Requires Specification/Confirmation: Math summary carries game name 'DogHouseMegaways9700'. Expected: identifier consistent between rules, math file and deployed config | K91: P1 | L91: High | M91: Compliance | N91: No | O91: QA / Staging (Game Client + RGS) | P91: Desktop + Mobile (all supported) | Q91: Not Run | S91: Ref: GR-59, M-20 | OBS-13

Sheet Math Validation
A1: Test Case ID | B1: Module | C1: Feature | D1: Sub-Feature | E1: Test Scenario | F1: Preconditions | G1: Test Data | H1: Detailed Test Steps | I1: Expected Result | J1: Actual Result | K1: Priority | L1: Severity | M1: Test Type | N1: Automation Candidate | O1: Environment | P1: Browser/Device | Q1: Status | R1: Defect ID | S1: Remarks
A2: PS-MTH-001 | B2: Math | C2: RTP | D2: Total RTP | E2: Verify total game RTP from a large simulation matches the math file | F2: Math simulation harness / RGS bulk-play tool (certified RNG, production math R7.1) | G2: Math: total RTP 96.98864% (1e9 sims); SD 16.80 x bet. 99% CI half-width = 2.576 x 16.80 / sqrt(N): N=1e8 => +/-0.433%; N=1e9 => +/-0.137% | H2: 1. Run N=1e9 base-game spins at bet 20 credits with random FS choice policy as used in math (see OBS-14) 2. Compute RTP = total win / total bet | I2: Simulated RTP within 96.98864% +/- 0.137% (99% CI). Fail outside the interval | K2: P0 | L2: Critical | M2: Math | N2: Yes | O2: QA / Staging (Game Client + RGS) | P2: N/A (RGS / Simulation) | Q2: Not Run | S2: Ref: M-01, M-03, GR-54 | OBS-14
A3: PS-MTH-002 | B3: Math | C3: RTP | D3: Base game RTP component | E3: Verify base game (non-FS) RTP contribution | F3: Math simulation harness / RGS bulk-play tool (certified RNG, production math R7.1) | G3: Math: base game RTP 68.92386% | H3: 1. From the same simulation sum base-game wins only 2. Divide by total bet | I3: Base RTP within 68.924% +/- statistical tolerance | K3: P0 | L3: Critical | M3: Math | N3: Yes | O3: QA / Staging (Game Client + RGS) | P3: N/A (RGS / Simulation) | Q3: Not Run | S3: Ref: M-01
A4: PS-MTH-003 | B4: Math | C4: RTP | D4: FS RTP component | E4: Verify Free Spins RTP contribution | F4: Math simulation harness / RGS bulk-play tool (certified RNG, production math R7.1) | G4: Math: FS RTP 28.06479%; avg FS win per trigger = 75.46x bet (E5) | H4: 1. Sum FS wins / total bet 2. Compute mean FS win per trigger / bet | I4: FS RTP ~28.065%; mean FS win ~75.46x bet within tolerance | K4: P0 | L4: Critical | M4: Math | N4: Yes | O4: QA / Staging (Game Client + RGS) | P4: N/A (RGS / Simulation) | Q4: Not Run | S4: Ref: M-01, M-18
A5: PS-MTH-004 | B5: Math | C5: RTP | D5: Per FS option RTP | E5: Verify RTP of Sticky Wilds FS and Raining Wilds FS when chosen at natural trigger | F5: Math simulation harness / RGS bulk-play tool (certified RNG, production math R7.1) | G5: Math file does not publish separate natural-trigger RTP per FS option | H5: 1. Simulate always-Sticky policy 2. Simulate always-Raining policy 3. Compute RTP for each | I5: Requires Specification/Confirmation: Expected per-option RTP values must be supplied by math provider. Both options must meet jurisdiction minimum RTP | K5: P0 | L5: Critical | M5: Math | N5: Yes | O5: QA / Staging (Game Client + RGS) | P5: N/A (RGS / Simulation) | Q5: Not Run | S5: Ref: M-01, GR-16 | OBS-14
A6: PS-MTH-005 | B6: Math | C6: RTP | D6: Buy FG1 RTP (Raining Wilds) | E6: Verify RTP of Buy Feature for FG1 (Raining Wilds: 15/18/25/30 FS) | F6: Math simulation harness / RGS bulk-play tool (certified RNG, production math R7.1) | G6: Math: Buy FG1 RTP 97.08362% (1e7 sims), SD 1.618 per buy (x cost). Cost 100x bet | H6: 1. Simulate 1e7 buys at bet 20 (cost 2000) 2. RTP = total win / total cost | I6: RTP within 97.084% +/- 2.576 x 1.618/sqrt(1e7) = +/-0.13% | K6: P0 | L6: Critical | M6: Math | N6: Yes | O6: QA / Staging (Game Client + RGS) | P6: N/A (RGS / Simulation) | Q6: Not Run | S6: Ref: M-15, GR-55
A7: PS-MTH-006 | B7: Math | C7: RTP | D7: Buy FG2 RTP (Sticky Wilds) | E7: Verify RTP of Buy Feature for FG2 (Sticky Wilds: 7/12/15/20 FS) | F7: Math simulation harness / RGS bulk-play tool (certified RNG, production math R7.1) | G7: Math: Buy FG2 RTP 97.10962%, SD 3.711 per buy | H7: 1. Simulate 1e7 buys 2. Compute RTP | I7: RTP within 97.110% +/- 2.576 x 3.711/sqrt(1e7) = +/-0.30% | K7: P0 | L7: Critical | M7: Math | N7: Yes | O7: QA / Staging (Game Client + RGS) | P7: N/A (RGS / Simulation) | Q7: Not Run | S7: Ref: M-16, GR-55
A8: PS-MTH-007 | B8: Math | C8: RTP | D8: Buy RTP >= base | E8: Verify Buy Feature RTP is not lower than base game RTP where jurisdiction requires | F8: Math summary | G8: Base 96.99%; Buy FG1 97.08%; Buy FG2 97.11% | H8: 1. Compare values | I8: Both Buy RTPs >= base RTP (97.08 and 97.11 >= 96.99): Pass | K8: P1 | L8: High | M8: Math | N8: No | O8: QA / Staging (Game Client + RGS) | P8: N/A (RGS / Simulation) | Q8: Not Run | S8: Ref: M-01, M-15, M-16
A9: PS-MTH-008 | B9: Math | C9: Hit Frequency | D9: Base hit frequency | E9: Verify hit frequency of winning base rounds | F9: Math simulation harness / RGS bulk-play tool (certified RNG, production math R7.1) | G9: Math: 31.6018% (1 in 3.164). 99% CI at N=1e7: +/-0.038% | H9: 1. Simulate 1e7 base spins 2. Count rounds with win > 0 | I9: Hit frequency within 31.602% +/- 0.038% | K9: P1 | L9: High | M9: Math | N9: Yes | O9: QA / Staging (Game Client + RGS) | P9: N/A (RGS / Simulation) | Q9: Not Run | S9: Ref: M-02
A10: PS-MTH-009 | B10: Math | C10: Hit Frequency | D10: Buy hit frequency | E10: Verify hit frequency of bought features | F10: Math simulation harness / RGS bulk-play tool (certified RNG, production math R7.1) | G10: Math: Buy FG1 99.99702%; Buy FG2 97.41966% | H10: 1. Simulate 1e7 buys per option 2. Count features with total win > 0 | I10: Values within statistical tolerance of math | K10: P2 | L10: Medium | M10: Math | N10: Yes | O10: QA / Staging (Game Client + RGS) | P10: N/A (RGS / Simulation) | Q10: Not Run | S10: Ref: M-15, M-16
A11: PS-MTH-010 | B11: Math | C11: Volatility | D11: Volatility index | E11: Verify volatility index / SD from simulation | F11: Math simulation harness / RGS bulk-play tool (certified RNG, production math R7.1) | G11: Math: SD 16.80; VI 90%=27.64, 95%=32.93, 99%=43.28 | H11: 1. Compute SD of round win (x bet) | I11: SD within +/-5% of 16.80; volatility classification in marketing material consistent (high volatility) | K11: P2 | L11: Medium | M11: Math | N11: Yes | O11: QA / Staging (Game Client + RGS) | P11: N/A (RGS / Simulation) | Q11: Not Run | S11: Ref: M-03
A12: PS-MTH-011 | B12: Math | C12: FS Trigger | D12: Trigger frequency | E12: Verify base game Free Spins trigger frequency | F12: Math simulation harness / RGS bulk-play tool (certified RNG, production math R7.1) | G12: Math: 1 in 268.89 spins (p = 0.003719). N=1e8 => expected 371,897 triggers; 99% CI +/- 1,571 | H12: 1. Simulate 1e8 spins 2. Count triggers | I12: Trigger count within expected +/- 99% CI | K12: P0 | L12: Critical | M12: Math | N12: Yes | O12: QA / Staging (Game Client + RGS) | P12: N/A (RGS / Simulation) | Q12: Not Run | S12: Ref: M-10, GR-14
A13: PS-MTH-012 | B13: Math | C13: FS Trigger | D13: Trigger by reel set | E13: Verify only reel sets BG1 and BG6 can produce a Free Spins trigger | F13: Math simulation harness / RGS bulk-play tool (certified RNG, production math R7.1) | G13: Math: FG trigger odds BG1 1 in 57.10, BG6 1 in 2.44, BG2-5/7-9 infinite | H13: 1. Log reel set ID per spin 2. Cross-tab triggers by reel set | I13: All triggers come from BG1 or BG6; observed odds within tolerance of 57.10 and 2.44 | K13: P1 | L13: High | M13: Math | N13: Yes | O13: QA / Staging (Game Client + RGS) | P13: N/A (RGS / Simulation) | Q13: Not Run | S13: Ref: M-09, M-10
... A64: PS-MTH-063 | B64: Math | C64: FS | D64: No natural wild on FS strips | E64: Verify Wilds in FS come only from feature placement (FS reel strips contain no WC) | F64: FG strips | G64: WC weight 0 on FG1/FG2 strips | H64: 1. Review strips | I64: No WC on FS strips | K64: P2 | L64: Medium | M64: Math | N64: No | O64: QA / Staging (Game Client + RGS) | P64: N/A (RGS / Simulation) | Q64: Not Run | S64: Ref: M-11, M-12

Sheet Feature Testing
A1: Test Case ID | B1: Module | C1: Feature | D1: Sub-Feature | E1: Test Scenario | F1: Preconditions | G1: Test Data | H1: Detailed Test Steps | I1: Expected Result | J1: Actual Result | K1: Priority | L1: Severity | M1: Test Type | N1: Automation Candidate | O1: Environment | P1: Browser/Device | Q1: Status | R1: Defect ID | S1: Remarks
A2: PS-FEA-001 | B2: Feature | C2: Sticky Wilds FS | D2: Min trigger | E2: Verify minimum trigger (3 BN) starts Sticky Wilds FS with 7 spins | F2: Forced 3 BN trigger | G2: 3 BN | H2: 1. Trigger 2. Select Sticky Wilds | I2: FS intro shown; counter 7; feature UI (counter, total win) visible | K2: P0 | L2: Critical | M2: Positive | N2: Yes | O2: QA / Staging (Game Client + RGS) | P2: Desktop + Mobile (all supported) | Q2: Not Run | S2: Ref: GR-05, GR-17, M-12
A3: PS-FEA-002 | B3: Feature | C3: Sticky Wilds FS | D3: Max trigger | E3: Verify maximum trigger (6 BN) starts Sticky Wilds FS with 20 spins | F3: Forced 6 BN trigger (1 on each reel) | G3: 6 BN | H3: 1. Trigger 2. Select option | I3: Counter 20 | K3: P0 | L3: Critical | M3: Boundary | N3: Yes | O3: QA / Staging (Game Client + RGS) | P3: Desktop + Mobile (all supported) | Q3: Not Run | S3: Ref: GR-05, GR-17, M-12 | OBS-16
A4: PS-FEA-003 | B4: Feature | C4: Sticky Wilds FS | D4: Completion | E4: Verify Sticky Wilds FS ends after the last spin and shows total feature win, then returns to base game | F4: Feature in progress | G4: Any | H4: 1. Play all spins 2. Observe end screen 3. Dismiss | I4: Counter reaches 0; summary shows total FS win = sum of spin wins; balance credited; base game restored at same bet | K4: P0 | L4: Critical | M4: Positive | N4: Yes | O4: QA / Staging (Game Client + RGS) | P4: Desktop + Mobile (all supported) | Q4: Not Run | S4: Ref: GR-05, GR-17, GR-12
A5: PS-FEA-004 | B5: Feature | C5: Sticky Wilds FS | D5: Counter | E5: Verify the Free Spins counter decrements by exactly 1 per spin in Sticky Wilds FS | F5: Feature in progress | G5: Award 7 | H5: 1. Observe counter before and after each spin | I5: Counter decrements by 1 each spin; never skips or repeats; no negative values | K5: P1 | L5: High | M5: Positive | N5: Yes | O5: QA / Staging (Game Client + RGS) | P5: Desktop + Mobile (all supported) | Q5: Not Run | S5: Ref: GR-05, GR-17
A6: PS-FEA-005 | B6: Feature | C6: Sticky Wilds FS | D6: Zero win feature | E6: Verify Sticky Wilds FS with no wins completes correctly showing total 0.00 | F6: Forced all-losing FS | G6: Award 7 | H6: 1. Play feature | I6: Feature ends with total 0.00; no credit transaction or 0.00 credit per RGS spec; base game restored | K6: P1 | L6: High | M6: Boundary | N6: Yes | O6: QA / Staging (Game Client + RGS) | P6: Desktop Chrome (latest) | Q6: Not Run | S6: Ref: GR-05, GR-17
A7: PS-FEA-006 | B7: Feature | C7: Sticky Wilds FS | D7: No retrigger | E7: Verify Bonus symbols do not appear and feature cannot retrigger in Sticky Wilds FS | F7: Feature in progress | G7: Award 20 | H7: 1. Play full feature observing reels | I7: No BN lands; no additional spins awarded | K7: P0 | L7: Critical | M7: Negative | N7: Yes | O7: QA / Staging (Game Client + RGS) | P7: Desktop + Mobile (all supported) | Q7: Not Run | S7: Ref: GR-18, M-08
A8: PS-FEA-007 | B8: Feature | C8: Sticky Wilds FS | D8: Bet | E8: Verify Sticky Wilds FS plays at trigger bet with no per-spin debit | F8: Trigger at max bet | G8: Max bet | H8: 1. Trigger at max bet 2. Play feature 3. Check balance during feature | I8: No debits; wins scaled to max bet | K8: P0 | L8: Critical | M8: Positive | N8: Yes | O8: QA / Staging (Game Client + RGS) | P8: Desktop + Mobile (all supported) | Q8: Not Run | S8: Ref: GR-15
A9: PS-FEA-008 | B9: Feature | C9: Sticky Wilds FS | D9: Win accumulation | E9: Verify total win meter accumulates each spin win during Sticky Wilds FS | F9: Forced wins on spins 1 and 3 | G9: Spin1 1.50, Spin3 3.00 | H9: 1. Play 2. Observe total meter | I9: Meter 1.50 after spin 1, 4.50 after spin 3; final summary 4.50 | K9: P0 | L9: Critical | M9: Positive | N9: Yes | O9: QA / Staging (Game Client + RGS) | P9: Desktop + Mobile (all supported) | Q9: Not Run | S9: Ref: GR-12
A10: PS-FEA-009 | B10: Feature | C10: Sticky Wilds FS | D10: Crediting timing | E10: Verify when Sticky Wilds FS winnings reach the player balance | F10: Feature in progress | G10: Forced wins | H10: 1. Note balance before feature 2. Observe balance during and after | I10: Requires Specification/Confirmation: Rules state 'All Free Spins winnings are awarded when the feature ends' under Raining Wilds only (OBS-08). Expected: balance unchanged during feature; credited once at end | K10: P0 | L10: Critical | M10: Positive | N10: Yes | O10: QA / Staging (Game Client + RGS) | P10: Desktop + Mobile (all supported) | Q10: Not Run | S10: Ref: GR-12 | OBS-08
A11: PS-FEA-010 | B11: Feature | C11: Sticky Wilds FS | D11: Refresh mid-feature | E11: Verify Sticky Wilds FS resumes after browser refresh with same remaining spins, wilds and total win | F11: Feature at spin 3 of 7 | G11: N/A | H11: 1. Refresh page after spin 3 completes 2. Reload game | I11: Feature resumes at spin 4; remaining count, accumulated win and (for Sticky) all sticky wilds with multipliers restored | K11: P0 | L11: Critical | M11: Recovery | N11: Yes | O11: QA / Staging (Game Client + RGS) | P11: Desktop + Mobile (all supported) | Q11: Not Run | S11: Ref: GR-56
A12: PS-FEA-011 | B12: Feature | C12: Sticky Wilds FS | D12: Refresh during spin | E12: Verify refresh while a Sticky Wilds FS spin is animating restores the already-determined result | F12: Feature spin in progress | G12: N/A | H12: 1. Start FS spin 2. Refresh before reels stop 3. Reload | I12: Result of that spin shown once (not replayed as new); counter reflects consumed spin; no duplicate win | K12: P0 | L12: Critical | M12: Recovery | N12: Yes | O12: QA / Staging (Game Client + RGS) | P12: Desktop + Mobile (all supported) | Q12: Not Run | S12: Ref: GR-56
A13: PS-FEA-012 | B13: Feature | C13: Sticky Wilds FS | D13: Max win in feature | E13: Verify reaching max win cap during Sticky Wilds FS ends the feature immediately | F13: Forced outcome exceeding cap | G13: Cap TBC | H13: 1. Force 2. Play | I13: Feature ends at cap; summary shows cap amount; remaining spins forfeited per rules | K13: P0 | L13: Critical | M13: Boundary | N13: Yes | O13: QA / Staging (Game Client + RGS) | P13: Desktop Chrome (latest) | Q13: Not Run | S13: Ref: GR-29 | OBS-09
... A60: PS-FEA-059 | B60: Feature | C60: Feature Recovery | D60: Feature end screen refresh | E60: Verify refresh on FS summary screen does not credit twice | F60: Summary screen visible | G60: Total 25.00 | H60: 1. Refresh 2. Reload | I60: Balance credited once; game returns to base idle or summary shown once | K60: P0 | L60: Critical | M60: Recovery | N60: Yes | O60: QA / Staging (Game Client + RGS) | P60: Desktop + Mobile (all supported) | Q60: Not Run | S60: Ref: GR-12, GR-56

Sheet Edge & Boundary Cases
A1: Test Case ID | B1: Module | C1: Feature | D1: Sub-Feature | E1: Test Scenario | F1: Preconditions | G1: Test Data | H1: Detailed Test Steps | I1: Expected Result | J1: Actual Result | K1: Priority | L1: Severity | M1: Test Type | N1: Automation Candidate | O1: Environment | P1: Browser/Device | Q1: Status | R1: Defect ID | S1: Remarks
A2: PS-EDG-001 | B2: Edge/Boundary | C2: Bet | D2: Min bet exact balance | E2: Verify spin is accepted at minimum bet when balance equals exactly the minimum bet and balance becomes 0.00 on loss | F2: Balance = min bet | G2: Min bet (TBC, e.g. 0.20); balance 0.20 | H2: 1. Set min bet 2. Spin (forced loss) | I2: Spin accepted; debit 0.20 once; balance 0.00; Play disabled or insufficient funds on next attempt | K2: P0 | L2: Critical | M2: Boundary | N2: Yes | O2: QA / Staging (Game Client + RGS) | P2: Desktop + Mobile (all supported) | Q2: Not Run | S2: Ref: GR-28, GR-22 | OBS-09
A3: PS-EDG-002 | B3: Edge/Boundary | C3: Bet | D3: Max bet exact balance | E3: Verify spin at maximum bet with balance exactly equal to max bet | F3: Balance = max bet | G3: Max bet (TBC) | H3: 1. Set max bet 2. Spin | I3: Accepted; single debit; balance updated with any win | K3: P0 | L3: Critical | M3: Boundary | N3: Yes | O3: QA / Staging (Game Client + RGS) | P3: Desktop + Mobile (all supported) | Q3: Not Run | S3: Ref: GR-28 | OBS-09
A4: PS-EDG-003 | B4: Edge/Boundary | C4: Balance | D4: Below min bet | E4: Verify spin is blocked when balance is 0.01 below the selected bet | F4: Balance = bet - 0.01 | G4: Bet 1.00; balance 0.99 | H4: 1. Spin | I4: Spin rejected; insufficient funds message; no debit | K4: P0 | L4: Critical | M4: Negative | N4: Yes | O4: QA / Staging (Game Client + RGS) | P4: Desktop + Mobile (all supported) | Q4: Not Run | S4: Ref: GR-22
A5: PS-EDG-004 | B5: Edge/Boundary | C5: Balance | D5: Zero balance | E5: Verify game behaviour with zero balance on launch | F5: Wallet 0.00 | G5: 0.00 | H5: 1. Launch 2. Press Play | I5: Game loads; Play rejected with insufficient funds and deposit link if configured; no RGS bet | K5: P0 | L5: Critical | M5: Negative | N5: Yes | O5: QA / Staging (Game Client + RGS) | P5: Desktop + Mobile (all supported) | Q5: Not Run | S5: Ref: GR-46
A6: PS-EDG-005 | B6: Edge/Boundary | C6: Balance | D6: Balance below bet, lower bet allowed | E6: Verify player can lower bet to continue playing when balance below current bet | F6: Balance 0.50, bet 1.00 | G6: Min bet 0.20 | H6: 1. Lower bet to 0.20 2. Spin | I6: Spin accepted at 0.20 | K6: P1 | L6: High | M6: Boundary | N6: Yes | O6: QA / Staging (Game Client + RGS) | P6: Desktop + Mobile (all supported) | Q6: Not Run | S6: Ref: GR-20
A7: PS-EDG-006 | B7: Edge/Boundary | C7: Buy | D7: Exact buy balance | E7: Verify Buy accepted when balance equals exactly 100x bet | F7: Balance 100.00, bet 1.00 | H7: 1. Buy | I7: Accepted; balance 0.00 before feature wins | K7: P0 | L7: Critical | M7: Boundary | N7: Yes | O7: QA / Staging (Game Client + RGS) | P7: Desktop + Mobile (all supported) | Q7: Not Run | S7: Ref: GR-36
A8: PS-EDG-007 | B8: Edge/Boundary | C8: Buy | D8: Min bet buy | E8: Verify Buy at minimum bet costs 100 x min bet | F8: Min bet | H8: 1. Open Buy at min bet | I8: Cost = 100 x min bet | K8: P1 | L8: High | M8: Boundary | N8: Yes | O8: QA / Staging (Game Client + RGS) | P8: Desktop + Mobile (all supported) | Q8: Not Run | S8: Ref: GR-36, GR-28 | OBS-09
A9: PS-EDG-008 | B9: Edge/Boundary | C9: Buy | D9: Max bet buy | E9: Verify Buy at maximum bet and display of large cost | F9: Max bet; sufficient balance | H9: 1. Open Buy at max bet 2. Confirm | I9: Cost = 100 x max bet shown fully formatted; single debit | K9: P1 | L9: High | M9: Boundary | N9: Yes | O9: QA / Staging (Game Client + RGS) | P9: Desktop + Mobile (all supported) | Q9: Not Run | S9: Ref: GR-36, GR-28
A10: PS-EDG-009 | B10: Edge/Boundary | C10: Win | D10: Large win display | E10: Verify display of a large win (>= 10,000x bet) with full digits and separators | F10: Forced large FS win | G10: Bet max; win 10,000x bet | H10: 1. Force 2. Play | I10: Win and balance shown fully; no overflow or scientific notation; Big Win sequence plays | K10: P0 | L10: Critical | M10: Boundary | N10: Yes | O10: QA / Staging (Game Client + RGS) | P10: Desktop + Mobile (all supported) | Q10: Not Run | S10: Ref: GR-25
A11: PS-EDG-010 | B11: Edge/Boundary | C11: Win | D11: Max win exact | E11: Verify win equal to the cap exactly is paid in full without truncation message error | F11: Forced win = cap | G11: Cap TBC | H11: 1. Force | I11: Win credited = cap; max win message per spec | K11: P0 | L11: Critical | M11: Boundary | N11: Yes | O11: QA / Staging (Game Client + RGS) | P11: Desktop + Mobile (all supported) | Q11: Not Run | S11: Ref: GR-29 | OBS-09
A12: PS-EDG-011 | B12: Edge/Boundary | C12: Win | D12: Max win +0.01 | E12: Verify win of cap + 0.01 is truncated to cap | F12: Forced | G12: Cap + 0.01 | H12: 1. Force | I12: Credited amount = cap | K12: P0 | L12: Critical | M12: Boundary | N12: Yes | O12: QA / Staging (Game Client + RGS) | P12: Desktop + Mobile (all supported) | Q12: Not Run | S12: Ref: GR-29 | OBS-09
A13: PS-EDG-012 | B13: Edge/Boundary | C13: Win | D13: Cap reached on triggering spin | E13: Verify base spin hitting cap while also landing 3 BN | F13: Forced | G13: Base win >= cap with 3 BN | H13: 1. Force | I13: Requires Specification/Confirmation: Expected: cap credited, FS not played (round ends) | K13: P1 | L13: High | M13: Boundary | N13: Yes | O13: QA / Staging (Game Client + RGS) | P13: Desktop + Mobile (all supported) | Q13: Not Run | S13: Ref: GR-29 | OBS-09
A14: PS-EDG-013 | B14: Edge/Boundary | C14: Win | D14: Many simultaneous wins | E14: Verify a spin with wins on 5+ symbols and thousands of ways evaluates and presents correctly | F14: Forced | G14: 7 rows all reels, mixed symbols | H14: 1. Force 2. Spin | I14: Total equals server; presentation cycles all wins; no freeze | K14: P1 | L14: High | M14: Boundary | N14: Yes | O14: QA / Staging (Game Client + RGS) | P14: Desktop + Mobile (all supported) | Q14: Not Run | S14: Ref: GR-25, GR-01
A15: PS-EDG-014 | B15: Edge/Boundary | C15: Win | D15: Max ways all same symbol | E15: Verify 117,649 ways of AA 6oak with no wilds | F15: Forced | G15: All 42 positions AA, bet 1.00 => 117,649 x 7.50 = 882,367.50 | H15: 1. Force | I15: Win 882,367.50 before cap; cap applied if configured lower | K15: P1 | L15: High | M15: Boundary | N15: Yes | O15: QA / Staging (Game Client + RGS) | P15: Desktop + Mobile (all supported) | Q15: Not Run | S15: Ref: GR-01, M-05, GR-29
A16: PS-EDG-015 | B16: Edge/Boundary | C16: Wild | D16: Max multiplier product | E16: Verify extreme multiplier product in Sticky FS (e.g. 28 stickies x3) is computed without overflow | F16: Forced FS | G16: Reels 2-5 all sticky x3 (7 rows) => product per way 3^4 = 81 per way; ways 7^6 | H16: 1. Force | I16: Server computes exact value; cap applied; no overflow/NaN | K16: P0 | L16: Critical | M16: Boundary | N16: Yes | O16: QA / Staging (Game Client + RGS) | P16: Desktop + Mobile (all supported) | Q16: Not Run | S16: Ref: GR-13, GR-29
A17: PS-EDG-016 | B17: Edge/Boundary | C17: Bonus | D17: Exactly 3 BN at max rows | E17: Verify 3 BN trigger when reels are at 7 rows | F17: Forced | G17: 3 BN, rows all 7 | H17: 1. Force | I17: Trigger | K17: P2 | L17: Medium | M17: Boundary | N17: Yes | O17: QA / Staging (Game Client + RGS) | P17: Desktop + Mobile (all supported) | Q17: Not Run | S17: Ref: GR-14
A18: PS-EDG-017 | B18: Edge/Boundary | C18: Bonus | D18: BN with min rows | E18: Verify 6 BN trigger with all reels at 2 rows | F18: Forced | G18: 6 BN, rows all 2 | H18: 1. Force | I18: Trigger with 6 BN award | K18: P2 | L18: Medium | M18: Boundary | N18: Yes | O18: QA / Staging (Game Client + RGS) | P18: Desktop + Mobile (all supported) | Q18: Not Run | S18: Ref: GR-14, GR-17
A19: PS-EDG-018 | B19: Edge/Boundary | C19: Bonus | D19: Two BN on same reel | E19: Verify whether two Bonus symbols can appear on one reel | F19: Strip review / forced | G19: N/A | H19: 1. Review strips for adjacent BN 2. Try force | I19: Requires Specification/Confirmation: Max BN per reel not defined (OBS-16). Expected per math: max 1 per reel visible | K19: P2 | L19: Medium | M19: Boundary | N19: No | O19: QA / Staging (Game Client + RGS) | P19: Desktop + Mobile (all supported) | Q19: Not Run | S19: Ref: GR-14 | OBS-16
A20: PS-EDG-019 | B20: Edge/Boundary | C20: Spin | D20: Spam Play | E20: Verify spam clicking Play (10 clicks/sec for 3s) starts only sequential rounds | F20: Bet 1.00 | H20: 1. Click Play repeatedly | I20: No overlapping rounds; each round debited once; no duplicate RGS requests | K20: P0 | L20: Critical | M20: Negative | N20: Yes | O20: QA / Staging (Game Client + RGS) | P20: Desktop + Mobile (all supported) | Q20: Not Run | S20: Ref: GR-22
A21: PS-EDG-020 | B21: Edge/Boundary | C21: Spin | D21: Space + click | E21: Verify pressing space and clicking Play simultaneously starts one round | F21: Desktop | H21: 1. Press space and click Play at same time | I21: One round only | K21: P1 | L21: High | M21: Negative | N21: Yes | O21: QA / Staging (Game Client + RGS) | P21: Desktop Chrome (latest) | Q21: Not Run | S21: Ref: GR-44
A22: PS-EDG-021 | B22: Edge/Boundary | C22: Spin | D22: Click during win | E22: Verify clicking Play during win presentation skips presentation and starts next round only once | F22: Win presentation running | H22: 1. Click Play during presentation | I22: Presentation skipped or next round starts per spec; win already credited; no double credit | K22: P1 | L22: High | M22: Boundary | N22: Yes | O22: QA / Staging (Game Client + RGS) | P22: Desktop + Mobile (all supported) | Q22: Not Run | S22: Ref: GR-22
A23: PS-EDG-022 | B23: Edge/Boundary | C23: Spin | D23: Click during transition | E23: Verify inputs during FS intro/outro transitions are ignored | F23: FS transition | H23: 1. Click Play/Bet/Menu during transition | I23: No action; transition completes; no stray spin | K23: P1 | L23: High | M23: Negative | N23: Yes | O23: QA / Staging (Game Client + RGS) | P23: Desktop + Mobile (all supported) | Q23: Not Run | S23: Ref: GR-16
A24: PS-EDG-023 | B24: Edge/Boundary | C24: Spin | D24: Buy during spin | E24: Verify Buy button disabled while reels spin | F24: Spin in progress | H24: 1. Click Buy during spin | I24: No interface opens | K24: P1 | L24: High | M24: Negative | N24: Yes | O24: QA / Staging (Game Client + RGS) | P24: Desktop + Mobile (all supported) | Q24: Not Run | S24: Ref: GR-32
A25: PS-EDG-024 | B25: Edge/Boundary | C25: Auto Spin | D25: Spend limit boundary | E25: Verify Auto Spin stops exactly when spend limit equals cumulative stake | F25: Bet 1.00 | G25: Spend limit 3.00 | H25: 1. Set 10 spins, limit 3.00 2. Force losses | I25: Requires Specification/Confirmation: Expected: 3 rounds then stop (limit inclusive) - confirm inclusive/exclusive | K25: P1 | L25: High | M25: Boundary | N25: Yes | O25: QA / Staging (Game Client + RGS) | P25: Desktop + Mobile (all supported) | Q25: Not Run | S25: Ref: GR-40 | OBS-21
A26: PS-EDG-025 | B26: Edge/Boundary | C26: Auto Spin | D26: Min/max count | E26: Verify the smallest and largest auto spin count options | F26: Auto menu | G26: Options per config | H26: 1. Select min 2. Run 3. Select max 4. Stop after 5 | I26: Counts honoured | K26: P2 | L26: Medium | M26: Boundary | N26: Yes | O26: QA / Staging (Game Client + RGS) | P26: Desktop + Mobile (all supported) | Q26: Not Run | S26: Ref: GR-38
A27: PS-EDG-026 | B27: Edge/Boundary | C27: Auto Spin | D27: Feature on last auto spin | E27: Verify FS triggered on the last auto spin completes and Auto Spin ends after | F27: Auto 5, trigger on 5th | H27: 1. Run | I27: Feature completes; Auto ends; remaining 0 | K27: P1 | L27: High | M27: Boundary | N27: Yes | O27: QA / Staging (Game Client + RGS) | P27: Desktop + Mobile (all supported) | Q27: Not Run | S27: Ref: GR-43
A28: PS-EDG-027 | B28: Edge/Boundary | C28: Auto Spin | D28: Stop pressed during FS | E28: Verify Stop pressed during auto-triggered FS | F28: Auto + FS | H28: 1. Press Stop during FS | I28: FS continues to completion (cannot be abandoned); auto stops after | K28: P1 | L28: High | M28: Boundary | N28: Yes | O28: QA / Staging (Game Client + RGS) | P28: Desktop + Mobile (all supported) | Q28: Not Run | S28: Ref: GR-43
A29: PS-EDG-028 | B29: Edge/Boundary | C29: Free Spins | D29: Last spin refresh | E29: Verify refresh during the last Free Spin | F29: Last FS spinning | H29: 1. Refresh | I29: Last result shown once; summary; single credit | K29: P0 | L29: Critical | M29: Recovery | N29: Yes | O29: QA / Staging (Game Client + RGS) | P29: Desktop + Mobile (all supported) | Q29: Not Run | S29: Ref: GR-56
A30: PS-EDG-029 | B30: Edge/Boundary | C30: Free Spins | D30: Refresh immediately after trigger | E30: Verify refresh immediately after 3 BN land (before choice) | F30: Trigger | H30: 1. Refresh within 500ms | I30: Choice screen restored | K30: P0 | L30: Critical | M30: Recovery | N30: Yes | O30: QA / Staging (Game Client + RGS) | P30: Desktop + Mobile (all supported) | Q30: Not Run | S30: Ref: GR-56, GR-16
A31: PS-EDG-030 | B31: Edge/Boundary | C31: Session | D31: Expired session spin | E31: Verify spin with expired session token | F31: Session expired by operator | H31: 1. Press Play | I31: Error shown; no debit; prompt to reload | K31: P0 | L31: Critical | M31: Negative | N31: Yes | O31: QA / Staging (Game Client + RGS) | P31: Desktop + Mobile (all supported) | Q31: Not Run | S31: Ref: GR-56
A32: PS-EDG-031 | B32: Edge/Boundary | C32: Session | D32: Timeout during FS | E32: Verify session timeout during FS | F32: FS in progress; operator timeout short | H32: 1. Idle until timeout 2. Relaunch | I32: Feature resumes after re-auth | K32: P0 | L32: Critical | M32: Recovery | N32: Yes | O32: QA / Staging (Game Client + RGS) | P32: Desktop + Mobile (all supported) | Q32: Not Run | S32: Ref: GR-56
A33: PS-EDG-032 | B33: Edge/Boundary | C33: Network | D33: Delayed response | E33: Verify UI behaviour with 10s server latency on spin | F33: Throttle 10s | H33: 1. Spin | I33: Reels keep spinning/loader; no second request; result shown when received | K33: P1 | L33: High | M33: Boundary | N33: Yes | O33: QA / Staging (Game Client + RGS) | P33: Desktop + Mobile (all supported) | Q33: Not Run | S33: Ref: GR-22
A34: PS-EDG-033 | B34: Edge/Boundary | C34: Network | D34: Response after timeout | E34: Verify late response after client timeout is reconciled | F34: Client timeout < server latency | H34: 1. Spin with latency > timeout | I34: Client recovers state from server on reconnect; balance consistent | K34: P0 | L34: Critical | M34: Recovery | N34: Yes | O34: QA / Staging (Game Client + RGS) | P34: Desktop + Mobile (all supported) | Q34: Not Run | S34: Ref: GR-56
A35: PS-EDG-034 | B35: Edge/Boundary | C35: Browser | D35: Back button | E35: Verify browser back during spin | F35: Spin in progress | H35: 1. Press back | I35: Leaves game or prompt; round completes server-side; on return state consistent | K35: P1 | L35: High | M35: Recovery | N35: Yes | O35: QA / Staging (Game Client + RGS) | P35: Desktop + Mobile (all supported) | Q35: Not Run | S35: Ref: GR-56
A36: PS-EDG-035 | B36: Edge/Boundary | C36: Browser | D36: Forward/back during FS | E36: Verify back then forward during FS | F36: FS | H36: 1. Back 2. Forward | I36: FS restored | K36: P1 | L36: High | M36: Recovery | N36: Yes | O36: QA / Staging (Game Client + RGS) | P36: Desktop + Mobile (all supported) | Q36: Not Run | S36: Ref: GR-56
A37: PS-EDG-036 | B37: Edge/Boundary | C37: Browser | D37: Multiple tabs | E37: Verify same game opened in two tabs for one session | F37: Tab A and Tab B | H37: 1. Spin in A 2. Spin in B | I37: Either single-session enforced or balance consistent; no double play of same FS | K37: P0 | L37: Critical | M37: Negative | N37: Yes | O37: QA / Staging (Game Client + RGS) | P37: Desktop + Mobile (all supported) | Q37: Not Run | S37: Ref: GR-56
A38: PS-EDG-037 | B38: Edge/Boundary | C38: Currency | D38: Decimal boundary | E38: Verify currency with 0 decimals and with 3 decimals display | F38: Sessions in non-decimal currency if supported | H38: 1. Spin 2. Check fields | I38: Precision correct | K38: P2 | L38: Medium | M38: Boundary | N38: Yes | O38: QA / Staging (Game Client + RGS) | P38: Desktop + Mobile (all supported) | Q38: Not Run | S38: Ref: GR-19
... A41: PS-EDG-040 | B41: Edge/Boundary | C41: Max Ways | D41: 7 rows on all reels FS | E41: Verify FS spin with all reels at 7 rows and sticky wilds | F41: Forced | H41: 1. Force | I41: Correct evaluation; layout fits | K41: P2 | L41: Medium | M41: Boundary | N41: Yes | O41: QA / Staging (Game Client + RGS) | P41: Desktop + Mobile (all supported) | Q41: Not Run | S41: Ref: GR-02, GR-08
A42: PS-EDG-041 | B42: Edge/Boundary | C42: Bet | D42: Bet change right before spin | E42: Verify changing bet and immediately pressing Play uses the new bet | F42: Bet 1.00 | G42: Change to 2.00 then Play within 200ms | H42: 1. Change 2. Spin | I42: Debit 2.00; RGS bet 2.00 | K42: P1 | L42: High | M42: Boundary | N42: Yes | O42: QA / Staging (Game Client + RGS) | P42: Desktop + Mobile (all supported) | Q42: Not Run | S42: Ref: GR-20
...

Sheet Regression Suite
A1: Test Case ID | B1: Module | C1: Feature | D1: Sub-Feature | E1: Test Scenario | F1: Preconditions | G1: Test Data | H1: Detailed Test Steps | I1: Expected Result | J1: Actual Result | K1: Priority | L1: Severity | M1: Test Type | N1: Automation Candidate | O1: Environment | P1: Browser/Device | Q1: Status | R1: Defect ID | S1: Remarks
A2: PS-REG-001 | B2: Regression (Functional) | C2: Game Launch | D2: Smoke | Initial load | E2: Verify the game launches from the operator lobby in real-money mode and lands on the base game with correct initial state | F2: Valid player session with funded wallet; game enabled for operator | G2: Balance: 500.00 EUR; default bet as configured | H2: 1. Log in to the operator lobby 2. Launch Pig Style 3. Wait for the loader to complete 4. Observe reels, bet field, balance field and win field | I2: Loader completes without error; 6 reels displayed; balance equals wallet balance (500.00); bet field shows configured default bet; win field shows 0.00 or blank; Play button enabled | K2: P0 | L2: Critical | M2: Regression | N2: Yes | O2: QA / Staging (Game Client + RGS) | P2: Desktop + Mobile (all supported) | Q2: Not Run | S2: Source: PS-FUN-001 (source priority P0) | Execute after: Code, UI, Configuration, CMS, Game engine
A3: PS-REG-002 | B3: Regression (Functional) | C3: Base Game | D3: Smoke | Reel layout | E3: Verify the base game shows 6 reels and each reel displays between 2 and 7 symbols per spin | F3: Base game loaded | G3: Observe 50 spins | H3: 1. Spin 50 times at any bet 2. For each spin, count visible symbol rows on every reel 3. Record min and max per reel | I3: Every reel shows a symbol count in the range 2..7 on every spin; no reel shows 1 or 8+ positions; reel heights vary independently per reel | K3: P0 | L3: Critical | M3: Regression | N3: Yes | O3: QA / Staging (Game Client + RGS) | P3: Desktop + Mobile (all supported) | Q3: Not Run | S3: Source: PS-FUN-005 (source priority P0) | Execute after: Code, UI, Configuration, CMS, Game engine
A4: PS-REG-003 | B4: Regression (Functional) | C4: Base Game | D4: Extended | Ways counter | E4: Verify the ways-to-win counter equals the product of the symbol counts on all 6 reels | F4: Base game loaded; ways counter visible | G4: Example rows [2,3,4,5,6,7] => 2x3x4x5x6x7 = 5,040 ways | H4: 1. Spin until a result is observed 2. Count rows on each reel 3. Multiply counts 4. Compare to on-screen ways counter | I4: Ways counter equals product of reel heights for every spin (e.g. 5,040 for [2,3,4,5,6,7]); counter updates when the reels stop | K4: P2 | L4: Critical | M4: Regression | N4: Yes | O4: QA / Staging (Game Client + RGS) | P4: Desktop + Mobile (all supported) | Q4: Not Run | S4: Source: PS-FUN-006 (source priority P0) | Execute after: Code, UI, Configuration, CMS, Game engine
A5: PS-REG-004 | B5: Regression (Functional) | C5: Spin | D5: Smoke | Start spin | E5: Verify pressing the Play button starts exactly one game round at the selected bet | F5: Balance >= selected bet | G5: Bet: 1.00; Balance: 100.00 | H5: 1. Note balance 2. Press Play once 3. Wait for round to complete | I5: One round starts; balance reduces by exactly 1.00 at spin start; one bet transaction in RGS; reels spin and stop; any win added after evaluation | K5: P0 | L5: Critical | M5: Regression | N5: Yes | O5: QA / Staging (Game Client + RGS) | P5: Desktop + Mobile (all supported) | Q5: Not Run | S5: Source: PS-FUN-009 (source priority P0) | Execute after: Code, UI, Configuration, CMS, Game engine
A6: PS-REG-005 | B6: Regression (Functional) | C6: Bet | D6: Extended | Limits | E6: Verify the increase control is disabled at maximum bet and decrease control disabled at minimum bet | F6: Bet panel open | G6: Min Bet / Max Bet: Requires Specification/Confirmation: values are {{text1}} in rules | H6: 1. Set bet to max; try increase 2. Set bet to min; try decrease | I6: Increase disabled/no effect at max; decrease disabled/no effect at min; bet never leaves configured range | K6: P2 | L6: Critical | M6: Regression | N6: Yes | O6: QA / Staging (Game Client + RGS) | P6: Desktop + Mobile (all supported) | Q6: Not Run | S6: Source: PS-FUN-016 (source priority P0) | Execute after: Code, UI, Configuration, CMS, Game engine
A7: PS-REG-006 | B7: Regression (Functional) | C7: Bet | D7: Extended | Bet lock | E7: Verify bet controls are disabled while reels are spinning and during win presentation | F7: Base game | G7: Bet: 1.00 | H7: 1. Press Play 2. While reels spin, attempt to open bet panel / change bet 3. During win presentation attempt to change bet | I7: Bet controls disabled or ignored during spin; bet of current round unchanged in RGS record | K7: P2 | L7: Critical | M7: Regression | N7: Yes | O7: QA / Staging (Game Client + RGS) | P7: Desktop + Mobile (all supported) | Q7: Not Run | S7: Source: PS-FUN-018 (source priority P0) | Execute after: Code, UI, Configuration, CMS, Game engine
A8: PS-REG-007 | B8: Regression (Functional) | C8: Bet | D8: Extended | Bet lock in Free Spins | E8: Verify bet cannot be changed during Free Spins | F8: Free Spins in progress (forced trigger) | G8: Trigger bet: 1.00 | H8: 1. Trigger Free Spins 2. During feature attempt to open bet panel | I8: Bet controls disabled for the whole feature; all Free Spins evaluated at 1.00 | K8: P2 | L8: Critical | M8: Regression | N8: Yes | O8: QA / Staging (Game Client + RGS) | P8: Desktop + Mobile (all supported) | Q8: Not Run | S8: Source: PS-FUN-019 (source priority P0) | Execute after: Code, UI, Configuration, CMS, Game engine
A9: PS-REG-008 | B9: Regression (Functional) | C9: Balance | D9: Smoke | Debit | E9: Verify the balance is debited by exactly the bet amount once per paid spin | F9: Funded balance | G9: Balance 100.00; Bet 0.20 (or min configured) | H9: 1. Note balance 2. Spin once with a losing result (forced) 3. Note balance | I9: Balance = 100.00 - 0.20 = 99.80; one debit transaction | K9: P0 | L9: Critical | M9: Regression | N9: Yes | O9: QA / Staging (Game Client + RGS) | P9: Desktop + Mobile (all supported) | Q9: Not Run | S9: Source: PS-FUN-020 (source priority P0) | Execute after: Code, UI, Configuration, CMS, Game engine
A10: PS-REG-009 | B10: Regression (Functional) | C10: Balance | D10: Smoke | Credit | E10: Verify a base game win is credited to the balance and shown in the win field | F10: Forced winning outcome | G10: Bet 1.00; outcome AA on reels 1-3 (1 way) => win 1.00 x 15/20 = 0.75 | H10: 1. Note balance B0 2. Spin with forced outcome 3. Read win field and balance | I10: Win field 0.75; final balance = B0 - 1.00 + 0.75; RGS win transaction amount 0.75 | K10: P0 | L10: Critical | M10: Regression | N10: Yes | O10: QA / Staging (Game Client + RGS) | P10: Desktop + Mobile (all supported) | Q10: Not Run | S10: Source: PS-FUN-021 (source priority P0) | Execute after: Code, UI, Configuration, CMS, Game engine
A11: PS-REG-010 | B11: Regression (Functional) | C11: Balance | D11: Core | Display sync | E11: Verify displayed balance matches the wallet balance after each round | F11: Wallet admin access | G11: 10 consecutive rounds | H11: 1. Play 10 rounds 2. After each round compare in-game balance with wallet backend balance | I11: Values match to the cent after every round | K11: P1 | L11: Critical | M11: Regression | N11: Yes | O11: QA / Staging (Game Client + RGS) | P11: Desktop + Mobile (all supported) | Q11: Not Run | S11: Source: PS-FUN-022 (source priority P0) | Execute after: Code, UI, Configuration, CMS, Game engine
A12: PS-REG-011 | B12: Regression (Functional) | C12: Paytable | D12: Extended | Symbol AA | E12: Verify paytable values for symbol AA for 3, 4, 5 and 6 of a kind at the current bet | F12: Game Info / paytable open | G12: Math pays (credits @ bet 20): 6=150, 5=60, 4=40, 3=15. At bet 1.00 => 6=7.50, 5=3.00, 4=2.00, 3=0.75 | H12: 1. Set bet 1.00 2. Open paytable 3. Read values for AA 4. Change bet to 2.00 and re-read | I12: At 1.00: 6x=7.50, 5x=3.00, 4x=2.00, 3x=0.75; at 2.00 all values double; no value shown for 2-of-a-kind (math has no 2oak pay, see OBS-03) | K12: P2 | L12: Critical | M12: Regression | N12: Yes | O12: QA / Staging (Game Client + RGS) | P12: Desktop + Mobile (all supported) | Q12: Not Run | S12: Source: PS-FUN-023 (source priority P0) | Execute after: Code, UI, Configuration, CMS, Game engine
A13: PS-REG-012 | B13: Regression (Functional) | C13: Paytable | D13: Extended | Bet scaling | E13: Verify all paytable values scale linearly when bet changes | F13: Paytable open | G13: Bets: min, 1.00, max | H13: 1. Open paytable at min bet and record all values 2. Repeat at 1.00 and at max | I13: Each value = bet x pay(credits)/20; ratios between bets exactly equal bet ratios; rounding per currency precision | K13: P2 | L13: Critical | M13: Regression | N13: Yes | O13: QA / Staging (Game Client + RGS) | P13: Desktop + Mobile (all supported) | Q13: Not Run | S13: Source: PS-FUN-034 (source priority P0) | Execute after: Code, UI, Configuration, CMS, Game engine
... A100: PS-REG-099 | B100: Regression (Edge/Boundary) | C100: Balance | D100: Core | Zero balance | E100: Verify game behaviour with zero balance on launch | F100: Wallet 0.00 | G100: 0.00 | H100: 1. Launch 2. Press Play | I100: Game loads; Play rejected with insufficient funds and deposit link if configured; no RGS bet | K100: P1 | L100: Critical | M100: Regression | N100: Yes | O100: QA / Staging (Game Client + RGS) | P100: Desktop + Mobile (all supported) | Q100: Not Run | S100: Source: PS-EDG-004 (source priority P0) | Execute after: Code, Wallet, Backend/API
A101: PS-REG-100 | B101: Regression (Edge/Boundary) | C101: Buy | D101: Extended | Exact buy balance | E101: Verify Buy accepted when balance equals exactly 100x bet | F101: Balance 100.00, bet 1.00 | H101: 1. Buy | I101: Accepted; balance 0.00 before feature wins | K101: P2 | L101: Critical | M101: Regression | N101: Yes | O101: QA / Staging (Game Client + RGS) | P101: Desktop + Mobile (all supported) | Q101: Not Run | S101: Source: PS-EDG-006 (source priority P0) | Execute after: Code, Wallet, Backend/API
A102: PS-REG-101 | B102: Regression (Edge/Boundary) | C102: Win | D102: Extended | Max win exact | E102: Verify win equal to the cap exactly is paid in full without truncation message error | F102: Forced win = cap | G102: Cap TBC | H102: 1. Force | I102: Win credited = cap; max win message per spec | K102: P2 | L102: Critical | M102: Regression | N102: Yes | O102: QA / Staging (Game Client + RGS) | P102: Desktop + Mobile (all supported) | Q102: Not Run | S102: Source: PS-EDG-010 (source priority P0) | Execute after: Code, Wallet, Backend/API
A103: PS-REG-102 | B103: Regression (Edge/Boundary) | C103: Win | D103: Extended | Max win +0.01 | E103: Verify win of cap + 0.01 is truncated to cap | F103: Forced | G103: Cap + 0.01 | H103: 1. Force | I103: Credited amount = cap | K103: P2 | L103: Critical | M103: Regression | N103: Yes | O103: QA / Staging (Game Client + RGS) | P103: Desktop + Mobile (all supported) | Q103: Not Run | S103: Source: PS-EDG-011 (source priority P0) | Execute after: Code, Wallet, Backend/API
A104: PS-REG-103 | B104: Regression (Edge/Boundary) | C104: Spin | D104: Core | Spam Play | E104: Verify spam clicking Play (10 clicks/sec for 3s) starts only sequential rounds | F104: Bet 1.00 | H104: 1. Click Play repeatedly | I104: No overlapping rounds; each round debited once; no duplicate RGS requests | K104: P1 | L104: Critical | M104: Regression | N104: Yes | O104: QA / Staging (Game Client + RGS) | P104: Desktop + Mobile (all supported) | Q104: Not Run | S104: Source: PS-EDG-019 (source priority P0) | Execute after: Code, Wallet, Backend/API
A105: PS-REG-104 | B105: Regression (UI/UX) | C105: Text | D105: Extended | Placeholders | E105: Verify no template placeholders like {{text1}} appear anywhere | F105: All screens | H105: 1. Search all text | I105: None present | K105: P2 | L105: Critical | M105: Regression | N105: Yes | O105: QA / Staging (Game Client + RGS) | P105: Desktop + Mobile (all supported) | Q105: Not Run | S105: Source: PS-UI-036 (source priority P0) | Execute after: UI, CMS
